Workbook

Sheet Start Here
B2: Round Robin & Ladder Organizer
B3: START HERE
B6: Cream cells | C6: Yours to fill in. Type, or pick from the drop-down lists.
B8: Beige cells | C8: Calculate by themselves. Please don't type over them.
B10: 1 · Setup | C10: Name your event, set the number of courts and the points for a win or tie, then list up to 16 players or doubles teams from the top, with no gaps.
B12: 2 · Schedule | C12: The full schedule appears instantly: every player meets every other player once, with court numbers. With an odd number of players, one player rests (a bye) each round.
B14: 3 · Enter scores | C14: Type the games won by each side, for example 6 and 4. The winner fills in by itself.
B16: 4 · Standings | C16: Ranked by points, then game difference, then games won. The Results Grid shows every score at a glance.
B18: Ladder | C18: For a season-long challenge ladder: list up to 20 players in starting order on the Ladder tab, then log each challenge on the Challenges tab. A challenger who beats a higher-ranked player takes their place, and everyone in between moves down one.
B20: Sample data | C20: The sample players and scores show how everything works. Before your event, clear the cream cells on Setup, the score columns on Schedule, and the Ladder and Challenges tabs.
B22: Changing players | C22: If you change the player list after scores are entered, clear the score columns first: the schedule is rebuilt for the new list.
B24: Google Sheets | C24: Upload this file to Google Drive, open it, then choose File › Save as Google Sheets. It also works in Microsoft Excel and Apple Numbers.
B26: Printing | C26: Each tab is set up to print on one page width. Print the Schedule for the noticeboard, or use the blank Draw Sheets PDF.
B28: For personal and single-club use. Thank you for supporting a small studio.

Sheet Setup
B2: Setup
B3: EVENT DETAILS AND PLAYERS
B6: Event name | C6: Saturday Social Round Robin
B7: Format | C7: Singles
B8: Courts available | C8: 3 | E8: Matches beyond the number of courts show “Next free”.
B9: Points for a win | C9: 1
B10: Points for a tie | C10: 0.5
B11: Match format (note) | C11: One set, first to 6 games
B12: Players entered | C12: =COUNTA($C$16:$C$31) -> 7 | E12: Enter at least 3. The schedule supports up to 16.
B13: Rounds | C13: =IF($C$12<3,0,$C$12+MOD($C$12,2)-1) -> 7 | E13: Every player meets every other player once.
B15: No. | C15: Player or doubles team
B16: 1 | C16: Anna | E16: For doubles, enter each team as one line, e.g. “Anna & Ben”.
B17: 2 | C17: Ben
B18: 3 | C18: Carla
B19: 4 | C19: David
B20: 5 | C20: Elena
B21: 6 | C21: Felix
B22: 7 | C22: Grace
B23: 8
B24: 9
B25: 10
B26: 11
B27: 12
B28: 13
B29: 14
B30: 15
B31: 16

Sheet Schedule
B2: Schedule
B3: CREATED AUTOMATICALLY · ENTER GAMES WON IN THE CREAM CELLS
B5: Round | C5: Court | D5: Player / team A | E5: Games A | F5: Games B | G5: Player / team B | H5: Winner
B6: =IF(L6,J6+1,"") -> 1 | C6: =IF(NOT(L6),"",IF(O6,"Bye",IF(IF(MOD(Setup!$C$12,2)=1,K6,K6+1)>Setup!$C$8,"Next free",IF(MOD(Setup!$C$12,2)=1,K6,K6+1)))) -> Bye | D6: =IF(NOT(L6),"",IF(M6>=Setup!$C$12,"Bye",INDEX(Setup!$C$16:$C$31,M6+1))) -> Anna | G6: =IF(NOT(L6),"",IF(N6>=Setup!$C$12,"Bye",INDEX(Setup!$C$16:$C$31,N6+1))) -> Bye | H6: =IF(OR(NOT(L6),O6,E6="",F6=""),"",IF(E6>F6,D6,IF(F6>E6,G6,"Tie"))) | J6: =IF(Setup!$C$13=0,"",INT(0/((Setup!$C$13+1)/2))) -> 0 | K6: =IF(Setup!$C$13=0,"",MOD(0,(Setup!$C$13+1)/2)) -> 0 | L6: =AND(Setup!$C$13>0,J6<Setup!$C$13) -> TRUE | M6: =IF(NOT(L6),"",IF(K6=0,J6,MOD(J6+K6,Setup!$C$13))) -> 0 | N6: =IF(NOT(L6),"",IF(K6=0,Setup!$C$13,MOD(J6-K6+Setup!$C$13,Setup!$C$13))) -> 7 | O6: =AND(L6,OR(M6>=Setup!$C$12,N6>=Setup!$C$12)) -> TRUE | P6: =IF(AND(L6,NOT(O6),E6<>"",F6<>""),1,0) -> 0 | Q6: =IF(L6,D6&"|"&G6,"") -> Anna|Bye | R6: =IF(L6,G6&"|"&D6,"") -> Bye|Anna
B7: =IF(L7,J7+1,"") -> 1 | C7: =IF(NOT(L7),"",IF(O7,"Bye",IF(IF(MOD(Setup!$C$12,2)=1,K7,K7+1)>Setup!$C$8,"Next free",IF(MOD(Setup!$C$12,2)=1,K7,K7+1)))) -> 1 | D7: =IF(NOT(L7),"",IF(M7>=Setup!$C$12,"Bye",INDEX(Setup!$C$16:$C$31,M7+1))) -> Ben | E7: 6 | F7: 3 | G7: =IF(NOT(L7),"",IF(N7>=Setup!$C$12,"Bye",INDEX(Setup!$C$16:$C$31,N7+1))) -> Grace | H7: =IF(OR(NOT(L7),O7,E7="",F7=""),"",IF(E7>F7,D7,IF(F7>E7,G7,"Tie"))) -> Ben | J7: =IF(Setup!$C$13=0,"",INT(1/((Setup!$C$13+1)/2))) -> 0 | K7: =IF(Setup!$C$13=0,"",MOD(1,(Setup!$C$13+1)/2)) -> 1 | L7: =AND(Setup!$C$13>0,J7<Setup!$C$13) -> TRUE | M7: =IF(NOT(L7),"",IF(K7=0,J7,MOD(J7+K7,Setup!$C$13))) -> 1 | N7: =IF(NOT(L7),"",IF(K7=0,Setup!$C$13,MOD(J7-K7+Setup!$C$13,Setup!$C$13))) -> 6 | O7: =AND(L7,OR(M7>=Setup!$C$12,N7>=Setup!$C$12)) -> FALSE | P7: =IF(AND(L7,NOT(O7),E7<>"",F7<>""),1,0) -> 1 | Q7: =IF(L7,D7&"|"&G7,"") -> Ben|Grace | R7: =IF(L7,G7&"|"&D7,"") -> Grace|Ben
B8: =IF(L8,J8+1,"") -> 1 | C8: =IF(NOT(L8),"",IF(O8,"Bye",IF(IF(MOD(Setup!$C$12,2)=1,K8,K8+1)>Setup!$C$8,"Next free",IF(MOD(Setup!$C$12,2)=1,K8,K8+1)))) -> 2 | D8: =IF(NOT(L8),"",IF(M8>=Setup!$C$12,"Bye",INDEX(Setup!$C$16:$C$31,M8+1))) -> Carla | E8: 4 | F8: 6 | G8: =IF(NOT(L8),"",IF(N8>=Setup!$C$12,"Bye",INDEX(Setup!$C$16:$C$31,N8+1))) -> Felix | H8: =IF(OR(NOT(L8),O8,E8="",F8=""),"",IF(E8>F8,D8,IF(F8>E8,G8,"Tie"))) -> Felix | J8: =IF(Setup!$C$13=0,"",INT(2/((Setup!$C$13+1)/2))) -> 0 | K8: =IF(Setup!$C$13=0,"",MOD(2,(Setup!$C$13+1)/2)) -> 2 | L8: =AND(Setup!$C$13>0,J8<Setup!$C$13) -> TRUE | M8: =IF(NOT(L8),"",IF(K8=0,J8,MOD(J8+K8,Setup!$C$13))) -> 2 | N8: =IF(NOT(L8),"",IF(K8=0,Setup!$C$13,MOD(J8-K8+Setup!$C$13,Setup!$C$13))) -> 5 | O8: =AND(L8,OR(M8>=Setup!$C$12,N8>=Setup!$C$12)) -> FALSE | P8: =IF(AND(L8,NOT(O8),E8<>"",F8<>""),1,0) -> 1 | Q8: =IF(L8,D8&"|"&G8,"") -> Carla|Felix | R8: =IF(L8,G8&"|"&D8,"") -> Felix|Carla
B9: =IF(L9,J9+1,"") -> 1 | C9: =IF(NOT(L9),"",IF(O9,"Bye",IF(IF(MOD(Setup!$C$12,2)=1,K9,K9+1)>Setup!$C$8,"Next free",IF(MOD(Setup!$C$12,2)=1,K9,K9+1)))) -> 3 | D9: =IF(NOT(L9),"",IF(M9>=Setup!$C$12,"Bye",INDEX(Setup!$C$16:$C$31,M9+1))) -> David | E9: 6 | F9: 2 | G9: =IF(NOT(L9),"",IF(N9>=Setup!$C$12,"Bye",INDEX(Setup!$C$16:$C$31,N9+1))) -> Elena | H9: =IF(OR(NOT(L9),O9,E9="",F9=""),"",IF(E9>F9,D9,IF(F9>E9,G9,"Tie"))) -> David | J9: =IF(Setup!$C$13=0,"",INT(3/((Setup!$C$13+1)/2))) -> 0 | K9: =IF(Setup!$C$13=0,"",MOD(3,(Setup!$C$13+1)/2)) -> 3 | L9: =AND(Setup!$C$13>0,J9<Setup!$C$13) -> TRUE | M9: =IF(NOT(L9),"",IF(K9=0,J9,MOD(J9+K9,Setup!$C$13))) -> 3 | N9: =IF(NOT(L9),"",IF(K9=0,Setup!$C$13,MOD(J9-K9+Setup!$C$13,Setup!$C$13))) -> 4 | O9: =AND(L9,OR(M9>=Setup!$C$12,N9>=Setup!$C$12)) -> FALSE | P9: =IF(AND(L9,NOT(O9),E9<>"",F9<>""),1,0) -> 1 | Q9: =IF(L9,D9&"|"&G9,"") -> David|Elena | R9: =IF(L9,G9&"|"&D9,"") -> Elena|David
B10: =IF(L10,J10+1,"") -> 2 | C10: =IF(NOT(L10),"",IF(O10,"Bye",IF(IF(MOD(Setup!$C$12,2)=1,K10,K10+1)>Setup!$C$8,"Next free",IF(MOD(Setup!$C$12,2)=1,K10,K10+1)))) -> Bye | D10: =IF(NOT(L10),"",IF(M10>=Setup!$C$12,"Bye",INDEX(Setup!$C$16:$C$31,M10+1))) -> Ben | G10: =IF(NOT(L10),"",IF(N10>=Setup!$C$12,"Bye",INDEX(Setup!$C$16:$C$31,N10+1))) -> Bye | H10: =IF(OR(NOT(L10),O10,E10="",F10=""),"",IF(E10>F10,D10,IF(F10>E10,G10,"Tie"))) | J10: =IF(Setup!$C$13=0,"",INT(4/((Setup!$C$13+1)/2))) -> 1 | K10: =IF(Setup!$C$13=0,"",MOD(4,(Setup!$C$13+1)/2)) -> 0 | L10: =AND(Setup!$C$13>0,J10<Setup!$C$13) -> TRUE | M10: =IF(NOT(L10),"",IF(K10=0,J10,MOD(J10+K10,Setup!$C$13))) -> 1 | N10: =IF(NOT(L10),"",IF(K10=0,Setup!$C$13,MOD(J10-K10+Setup!$C$13,Setup!$C$13))) -> 7 | O10: =AND(L10,OR(M10>=Setup!$C$12,N10>=Setup!$C$12)) -> TRUE | P10: =IF(AND(L10,NOT(O10),E10<>"",F10<>""),1,0) -> 0 | Q10: =IF(L10,D10&"|"&G10,"") -> Ben|Bye | R10: =IF(L10,G10&"|"&D10,"") -> Bye|Ben
B11: =IF(L11,J11+1,"") -> 2 | C11: =IF(NOT(L11),"",IF(O11,"Bye",IF(IF(MOD(Setup!$C$12,2)=1,K11,K11+1)>Setup!$C$8,"Next free",IF(MOD(Setup!$C$12,2)=1,K11,K11+1)))) -> 1 | D11: =IF(NOT(L11),"",IF(M11>=Setup!$C$12,"Bye",INDEX(Setup!$C$16:$C$31,M11+1))) -> Carla | E11: 6 | F11: 4 | G11: =IF(NOT(L11),"",IF(N11>=Setup!$C$12,"Bye",INDEX(Setup!$C$16:$C$31,N11+1))) -> Anna | H11: =IF(OR(NOT(L11),O11,E11="",F11=""),"",IF(E11>F11,D11,IF(F11>E11,G11,"Tie"))) -> Carla | J11: =IF(Setup!$C$13=0,"",INT(5/((Setup!$C$13+1)/2))) -> 1 | K11: =IF(Setup!$C$13=0,"",MOD(5,(Setup!$C$13+1)/2)) -> 1 | L11: =AND(Setup!$C$13>0,J11<Setup!$C$13) -> TRUE | M11: =IF(NOT(L11),"",IF(K11=0,J11,MOD(J11+K11,Setup!$C$13))) -> 2 | N11: =IF(NOT(L11),"",IF(K11=0,Setup!$C$13,MOD(J11-K11+Setup!$C$13,Setup!$C$13))) -> 0 | O11: =AND(L11,OR(M11>=Setup!$C$12,N11>=Setup!$C$12)) -> FALSE | P11: =IF(AND(L11,NOT(O11),E11<>"",F11<>""),1,0) -> 1 | Q11: =IF(L11,D11&"|"&G11,"") -> Carla|Anna | R11: =IF(L11,G11&"|"&D11,"") -> Anna|Carla
B12: =IF(L12,J12+1,"") -> 2 | C12: =IF(NOT(L12),"",IF(O12,"Bye",IF(IF(MOD(Setup!$C$12,2)=1,K12,K12+1)>Setup!$C$8,"Next free",IF(MOD(Setup!$C$12,2)=1,K12,K12+1)))) -> 2 | D12: =IF(NOT(L12),"",IF(M12>=Setup!$C$12,"Bye",INDEX(Setup!$C$16:$C$31,M12+1))) -> David | E12: 5 | F12: 6 | G12: =IF(NOT(L12),"",IF(N12>=Setup!$C$12,"Bye",INDEX(Setup!$C$16:$C$31,N12+1))) -> Grace | H12: =IF(OR(NOT(L12),O12,E12="",F12=""),"",IF(E12>F12,D12,IF(F12>E12,G12,"Tie"))) -> Grace | J12: =IF(Setup!$C$13=0,"",INT(6/((Setup!$C$13+1)/2))) -> 1 | K12: =IF(Setup!$C$13=0,"",MOD(6,(Setup!$C$13+1)/2)) -> 2 | L12: =AND(Setup!$C$13>0,J12<Setup!$C$13) -> TRUE | M12: =IF(NOT(L12),"",IF(K12=0,J12,MOD(J12+K12,Setup!$C$13))) -> 3 | N12: =IF(NOT(L12),"",IF(K12=0,Setup!$C$13,MOD(J12-K12+Setup!$C$13,Setup!$C$13))) -> 6 | O12: =AND(L12,OR(M12>=Setup!$C$12,N12>=Setup!$C$12)) -> FALSE | P12: =IF(AND(L12,NOT(O12),E12<>"",F12<>""),1,0) -> 1 | Q12: =IF(L12,D12&"|"&G12,"") -> David|Grace | R12: =IF(L12,G12&"|"&D12,"") -> Grace|David
B13: =IF(L13,J13+1,"") -> 2 | C13: =IF(NOT(L13),"",IF(O13,"Bye",IF(IF(MOD(Setup!$C$12,2)=1,K13,K13+1)>Setup!$C$8,"Next free",IF(MOD(Setup!$C$12,2)=1,K13,K13+1)))) -> 3 | D13: =IF(NOT(L13),"",IF(M13>=Setup!$C$12,"Bye",INDEX(Setup!$C$16:$C$31,M13+1))) -> Elena | E13: 6 | F13: 1 | G13: =IF(NOT(L13),"",IF(N13>=Setup!$C$12,"Bye",INDEX(Setup!$C$16:$C$31,N13+1))) -> Felix | H13: =IF(OR(NOT(L13),O13,E13="",F13=""),"",IF(E13>F13,D13,IF(F13>E13,G13,"Tie"))) -> Elena | J13: =IF(Setup!$C$13=0,"",INT(7/((Setup!$C$13+1)/2))) -> 1 | K13: =IF(Setup!$C$13=0,"",MOD(7,(Setup!$C$13+1)/2)) -> 3 | L13: =AND(Setup!$C$13>0,J13<Setup!$C$13) -> TRUE | M13: =IF(NOT(L13),"",IF(K13=0,J13,MOD(J13+K13,Setup!$C$13))) -> 4 | N13: =IF(NOT(L13),"",IF(K13=0,Setup!$C$13,MOD(J13-K13+Setup!$C$13,Setup!$C$13))) -> 5 | O13: =AND(L13,OR(M13>=Setup!$C$12,N13>=Setup!$C$12)) -> FALSE | P13: =IF(AND(L13,NOT(O13),E13<>"",F13<>""),1,0) -> 1 | Q13: =IF(L13,D13&"|"&G13,"") -> Elena|Felix | R13: =IF(L13,G13&"|"&D13,"") -> Felix|Elena
B14: =IF(L14,J14+1,"") -> 3 | C14: =IF(NOT(L14),"",IF(O14,"Bye",IF(IF(MOD(Setup!$C$12,2)=1,K14,K14+1)>Setup!$C$8,"Next free",IF(MOD(Setup!$C$12,2)=1,K14,K14+1)))) -> Bye | D14: =IF(NOT(L14),"",IF(M14>=Setup!$C$12,"Bye",INDEX(Setup!$C$16:$C$31,M14+1))) -> Carla | G14: =IF(NOT(L14),"",IF(N14>=Setup!$C$12,"Bye",INDEX(Setup!$C$16:$C$31,N14+1))) -> Bye | H14: =IF(OR(NOT(L14),O14,E14="",F14=""),"",IF(E14>F14,D14,IF(F14>E14,G14,"Tie"))) | J14: =IF(Setup!$C$13=0,"",INT(8/((Setup!$C$13+1)/2))) -> 2 | K14: =IF(Setup!$C$13=0,"",MOD(8,(Setup!$C$13+1)/2)) -> 0 | L14: =AND(Setup!$C$13>0,J14<Setup!$C$13) -> TRUE | M14: =IF(NOT(L14),"",IF(K14=0,J14,MOD(J14+K14,Setup!$C$13))) -> 2 | N14: =IF(NOT(L14),"",IF(K14=0,Setup!$C$13,MOD(J14-K14+Setup!$C$13,Setup!$C$13))) -> 7 | O14: =AND(L14,OR(M14>=Setup!$C$12,N14>=Setup!$C$12)) -> TRUE | P14: =IF(AND(L14,NOT(O14),E14<>"",F14<>""),1,0) -> 0 | Q14: =IF(L14,D14&"|"&G14,"") -> Carla|Bye | R14: =IF(L14,G14&"|"&D14,"") -> Bye|Carla
B15: =IF(L15,J15+1,"") -> 3 | C15: =IF(NOT(L15),"",IF(O15,"Bye",IF(IF(MOD(Setup!$C$12,2)=1,K15,K15+1)>Setup!$C$8,"Next free",IF(MOD(Setup!$C$12,2)=1,K15,K15+1)))) -> 1 | D15: =IF(NOT(L15),"",IF(M15>=Setup!$C$12,"Bye",INDEX(Setup!$C$16:$C$31,M15+1))) -> David | E15: 3 | F15: 6 | G15: =IF(NOT(L15),"",IF(N15>=Setup!$C$12,"Bye",INDEX(Setup!$C$16:$C$31,N15+1))) -> Ben | H15: =IF(OR(NOT(L15),O15,E15="",F15=""),"",IF(E15>F15,D15,IF(F15>E15,G15,"Tie"))) -> Ben | J15: =IF(Setup!$C$13=0,"",INT(9/((Setup!$C$13+1)/2))) -> 2 | K15: =IF(Setup!$C$13=0,"",MOD(9,(Setup!$C$13+1)/2)) -> 1 | L15: =AND(Setup!$C$13>0,J15<Setup!$C$13) -> TRUE | M15: =IF(NOT(L15),"",IF(K15=0,J15,MOD(J15+K15,Setup!$C$13))) -> 3 | N15: =IF(NOT(L15),"",IF(K15=0,Setup!$C$13,MOD(J15-K15+Setup!$C$13,Setup!$C$13))) -> 1 | O15: =AND(L15,OR(M15>=Setup!$C$12,N15>=Setup!$C$12)) -> FALSE | P15: =IF(AND(L15,NOT(O15),E15<>"",F15<>""),1,0) -> 1 | Q15: =IF(L15,D15&"|"&G15,"") -> David|Ben | R15: =IF(L15,G15&"|"&D15,"") -> Ben|David
B16: =IF(L16,J16+1,"") -> 3 | C16: =IF(NOT(L16),"",IF(O16,"Bye",IF(IF(MOD(Setup!$C$12,2)=1,K16,K16+1)>Setup!$C$8,"Next free",IF(MOD(Setup!$C$12,2)=1,K16,K16+1)))) -> 2 | D16: =IF(NOT(L16),"",IF(M16>=Setup!$C$12,"Bye",INDEX(Setup!$C$16:$C$31,M16+1))) -> Elena | E16: 5 | F16: 5 | G16: =IF(NOT(L16),"",IF(N16>=Setup!$C$12,"Bye",INDEX(Setup!$C$16:$C$31,N16+1))) -> Anna | H16: =IF(OR(NOT(L16),O16,E16="",F16=""),"",IF(E16>F16,D16,IF(F16>E16,G16,"Tie"))) -> Tie | J16: =IF(Setup!$C$13=0,"",INT(10/((Setup!$C$13+1)/2))) -> 2 | K16: =IF(Setup!$C$13=0,"",MOD(10,(Setup!$C$13+1)/2)) -> 2 | L16: =AND(Setup!$C$13>0,J16<Setup!$C$13) -> TRUE | M16: =IF(NOT(L16),"",IF(K16=0,J16,MOD(J16+K16,Setup!$C$13))) -> 4 | N16: =IF(NOT(L16),"",IF(K16=0,Setup!$C$13,MOD(J16-K16+Setup!$C$13,Setup!$C$13))) -> 0 | O16: =AND(L16,OR(M16>=Setup!$C$12,N16>=Setup!$C$12)) -> FALSE | P16: =IF(AND(L16,NOT(O16),E16<>"",F16<>""),1,0) -> 1 | Q16: =IF(L16,D16&"|"&G16,"") -> Elena|Anna | R16: =IF(L16,G16&"|"&D16,"") -> Anna|Elena
B17: =IF(L17,J17+1,"") -> 3 | C17: =IF(NOT(L17),"",IF(O17,"Bye",IF(IF(MOD(Setup!$C$12,2)=1,K17,K17+1)>Setup!$C$8,"Next free",IF(MOD(Setup!$C$12,2)=1,K17,K17+1)))) -> 3 | D17: =IF(NOT(L17),"",IF(M17>=Setup!$C$12,"Bye",INDEX(Setup!$C$16:$C$31,M17+1))) -> Felix | E17: 6 | F17: 0 | G17: =IF(NOT(L17),"",IF(N17>=Setup!$C$12,"Bye",INDEX(Setup!$C$16:$C$31,N17+1))) -> Grace | H17: =IF(OR(NOT(L17),O17,E17="",F17=""),"",IF(E17>F17,D17,IF(F17>E17,G17,"Tie"))) -> Felix | J17: =IF(Setup!$C$13=0,"",INT(11/((Setup!$C$13+1)/2))) -> 2 | K17: =IF(Setup!$C$13=0,"",MOD(11,(Setup!$C$13+1)/2)) -> 3 | L17: =AND(Setup!$C$13>0,J17<Setup!$C$13) -> TRUE | M17: =IF(NOT(L17),"",IF(K17=0,J17,MOD(J17+K17,Setup!$C$13))) -> 5 | N17: =IF(NOT(L17),"",IF(K17=0,Setup!$C$13,MOD(J17-K17+Setup!$C$13,Setup!$C$13))) -> 6 | O17: =AND(L17,OR(M17>=Setup!$C$12,N17>=Setup!$C$12)) -> FALSE | P17: =IF(AND(L17,NOT(O17),E17<>"",F17<>""),1,0) -> 1 | Q17: =IF(L17,D17&"|"&G17,"") -> Felix|Grace | R17: =IF(L17,G17&"|"&D17,"") -> Grace|Felix
B18: =IF(L18,J18+1,"") -> 4 | C18: =IF(NOT(L18),"",IF(O18,"Bye",IF(IF(MOD(Setup!$C$12,2)=1,K18,K18+1)>Setup!$C$8,"Next free",IF(MOD(Setup!$C$12,2)=1,K18,K18+1)))) -> Bye | D18: =IF(NOT(L18),"",IF(M18>=Setup!$C$12,"Bye",INDEX(Setup!$C$16:$C$31,M18+1))) -> David | G18: =IF(NOT(L18),"",IF(N18>=Setup!$C$12,"Bye",INDEX(Setup!$C$16:$C$31,N18+1))) -> Bye | H18: =IF(OR(NOT(L18),O18,E18="",F18=""),"",IF(E18>F18,D18,IF(F18>E18,G18,"Tie"))) | J18: =IF(Setup!$C$13=0,"",INT(12/((Setup!$C$13+1)/2))) -> 3 | K18: =IF(Setup!$C$13=0,"",MOD(12,(Setup!$C$13+1)/2)) -> 0 | L18: =AND(Setup!$C$13>0,J18<Setup!$C$13) -> TRUE | M18: =IF(NOT(L18),"",IF(K18=0,J18,MOD(J18+K18,Setup!$C$13))) -> 3 | N18: =IF(NOT(L18),"",IF(K18=0,Setup!$C$13,MOD(J18-K18+Setup!$C$13,Setup!$C$13))) -> 7 | O18: =AND(L18,OR(M18>=Setup!$C$12,N18>=Setup!$C$12)) -> TRUE | P18: =IF(AND(L18,NOT(O18),E18<>"",F18<>""),1,0) -> 0 | Q18: =IF(L18,D18&"|"&G18,"") -> David|Bye | R18: =IF(L18,G18&"|"&D18,"") -> Bye|David
B19: =IF(L19,J19+1,"") -> 4 | C19: =IF(NOT(L19),"",IF(O19,"Bye",IF(IF(MOD(Setup!$C$12,2)=1,K19,K19+1)>Setup!$C$8,"Next free",IF(MOD(Setup!$C$12,2)=1,K19,K19+1)))) -> 1 | D19: =IF(NOT(L19),"",IF(M19>=Setup!$C$12,"Bye",INDEX(Setup!$C$16:$C$31,M19+1))) -> Elena | G19: =IF(NOT(L19),"",IF(N19>=Setup!$C$12,"Bye",INDEX(Setup!$C$16:$C$31,N19+1))) -> Carla | H19: =IF(OR(NOT(L19),O19,E19="",F19=""),"",IF(E19>F19,D19,IF(F19>E19,G19,"Tie"))) | J19: =IF(Setup!$C$13=0,"",INT(13/((Setup!$C$13+1)/2))) -> 3 | K19: =IF(Setup!$C$13=0,"",MOD(13,(Setup!$C$13+1)/2)) -> 1 | L19: =AND(Setup!$C$13>0,J19<Setup!$C$13) -> TRUE | M19: =IF(NOT(L19),"",IF(K19=0,J19,MOD(J19+K19,Setup!$C$13))) -> 4 | N19: =IF(NOT(L19),"",IF(K19=0,Setup!$C$13,MOD(J19-K19+Setup!$C$13,Setup!$C$13))) -> 2 | O19: =AND(L19,OR(M19>=Setup!$C$12,N19>=Setup!$C$12)) -> FALSE | P19: =IF(AND(L19,NOT(O19),E19<>"",F19<>""),1,0) -> 0 | Q19: =IF(L19,D19&"|"&G19,"") -> Elena|Carla | R19: =IF(L19,G19&"|"&D19,"") -> Carla|Elena
B20: =IF(L20,J20+1,"") -> 4 | C20: =IF(NOT(L20),"",IF(O20,"Bye",IF(IF(MOD(Setup!$C$12,2)=1,K20,K20+1)>Setup!$C$8,"Next free",IF(MOD(Setup!$C$12,2)=1,K20,K20+1)))) -> 2 | D20: =IF(NOT(L20),"",IF(M20>=Setup!$C$12,"Bye",INDEX(Setup!$C$16:$C$31,M20+1))) -> Felix | G20: =IF(NOT(L20),"",IF(N20>=Setup!$C$12,"Bye",INDEX(Setup!$C$16:$C$31,N20+1))) -> Ben | H20: =IF(OR(NOT(L20),O20,E20="",F20=""),"",IF(E20>F20,D20,IF(F20>E20,G20,"Tie"))) | J20: =IF(Setup!$C$13=0,"",INT(14/((Setup!$C$13+1)/2))) -> 3 | K20: =IF(Setup!$C$13=0,"",MOD(14,(Setup!$C$13+1)/2)) -> 2 | L20: =AND(Setup!$C$13>0,J20<Setup!$C$13) -> TRUE | M20: =IF(NOT(L20),"",IF(K20=0,J20,MOD(J20+K20,Setup!$C$13))) -> 5 | N20: =IF(NOT(L20),"",IF(K20=0,Setup!$C$13,MOD(J20-K20+Setup!$C$13,Setup!$C$13))) -> 1 | O20: =AND(L20,OR(M20>=Setup!$C$12,N20>=Setup!$C$12)) -> FALSE | P20: =IF(AND(L20,NOT(O20),E20<>"",F20<>""),1,0) -> 0 | Q20: =IF(L20,D20&"|"&G20,"") -> Felix|Ben | R20: =IF(L20,G20&"|"&D20,"") -> Ben|Felix
B21: =IF(L21,J21+1,"") -> 4 | C21: =IF(NOT(L21),"",IF(O21,"Bye",IF(IF(MOD(Setup!$C$12,2)=1,K21,K21+1)>Setup!$C$8,"Next free",IF(MOD(Setup!$C$12,2)=1,K21,K21+1)))) -> 3 | D21: =IF(NOT(L21),"",IF(M21>=Setup!$C$12,"Bye",INDEX(Setup!$C$16:$C$31,M21+1))) -> Grace | G21: =IF(NOT(L21),"",IF(N21>=Setup!$C$12,"Bye",INDEX(Setup!$C$16:$C$31,N21+1))) -> Anna | H21: =IF(OR(NOT(L21),O21,E21="",F21=""),"",IF(E21>F21,D21,IF(F21>E21,G21,"Tie"))) | J21: =IF(Setup!$C$13=0,"",INT(15/((Setup!$C$13+1)/2))) -> 3 | K21: =IF(Setup!$C$13=0,"",MOD(15,(Setup!$C$13+1)/2)) -> 3 | L21: =AND(Setup!$C$13>0,J21<Setup!$C$13) -> TRUE | M21: =IF(NOT(L21),"",IF(K21=0,J21,MOD(J21+K21,Setup!$C$13))) -> 6 | N21: =IF(NOT(L21),"",IF(K21=0,Setup!$C$13,MOD(J21-K21+Setup!$C$13,Setup!$C$13))) -> 0 | O21: =AND(L21,OR(M21>=Setup!$C$12,N21>=Setup!$C$12)) -> FALSE | P21: =IF(AND(L21,NOT(O21),E21<>"",F21<>""),1,0) -> 0 | Q21: =IF(L21,D21&"|"&G21,"") -> Grace|Anna | R21: =IF(L21,G21&"|"&D21,"") -> Anna|Grace
B22: =IF(L22,J22+1,"") -> 5 | C22: =IF(NOT(L22),"",IF(O22,"Bye",IF(IF(MOD(Setup!$C$12,2)=1,K22,K22+1)>Setup!$C$8,"Next free",IF(MOD(Setup!$C$12,2)=1,K22,K22+1)))) -> Bye | D22: =IF(NOT(L22),"",IF(M22>=Setup!$C$12,"Bye",INDEX(Setup!$C$16:$C$31,M22+1))) -> Elena | G22: =IF(NOT(L22),"",IF(N22>=Setup!$C$12,"Bye",INDEX(Setup!$C$16:$C$31,N22+1))) -> Bye | H22: =IF(OR(NOT(L22),O22,E22="",F22=""),"",IF(E22>F22,D22,IF(F22>E22,G22,"Tie"))) | J22: =IF(Setup!$C$13=0,"",INT(16/((Setup!$C$13+1)/2))) -> 4 | K22: =IF(Setup!$C$13=0,"",MOD(16,(Setup!$C$13+1)/2)) -> 0 | L22: =AND(Setup!$C$13>0,J22<Setup!$C$13) -> TRUE | M22: =IF(NOT(L22),"",IF(K22=0,J22,MOD(J22+K22,Setup!$C$13))) -> 4 | N22: =IF(NOT(L22),"",IF(K22=0,Setup!$C$13,MOD(J22-K22+Setup!$C$13,Setup!$C$13))) -> 7 | O22: =AND(L22,OR(M22>=Setup!$C$12,N22>=Setup!$C$12)) -> TRUE | P22: =IF(AND(L22,NOT(O22),E22<>"",F22<>""),1,0) -> 0 | Q22: =IF(L22,D22&"|"&G22,"") -> Elena|Bye | R22: =IF(L22,G22&"|"&D22,"") -> Bye|Elena
B23: =IF(L23,J23+1,"") -> 5 | C23: =IF(NOT(L23),"",IF(O23,"Bye",IF(IF(MOD(Setup!$C$12,2)=1,K23,K23+1)>Setup!$C$8,"Next free",IF(MOD(Setup!$C$12,2)=1,K23,K23+1)))) -> 1 | D23: =IF(NOT(L23),"",IF(M23>=Setup!$C$12,"Bye",INDEX(Setup!$C$16:$C$31,M23+1))) -> Felix | G23: =IF(NOT(L23),"",IF(N23>=Setup!$C$12,"Bye",INDEX(Setup!$C$16:$C$31,N23+1))) -> David | H23: =IF(OR(NOT(L23),O23,E23="",F23=""),"",IF(E23>F23,D23,IF(F23>E23,G23,"Tie"))) | J23: =IF(Setup!$C$13=0,"",INT(17/((Setup!$C$13+1)/2))) -> 4 | K23: =IF(Setup!$C$13=0,"",MOD(17,(Setup!$C$13+1)/2)) -> 1 | L23: =AND(Setup!$C$13>0,J23<Setup!$C$13) -> TRUE | M23: =IF(NOT(L23),"",IF(K23=0,J23,MOD(J23+K23,Setup!$C$13))) -> 5 | N23: =IF(NOT(L23),"",IF(K23=0,Setup!$C$13,MOD(J23-K23+Setup!$C$13,Setup!$C$13))) -> 3 | O23: =AND(L23,OR(M23>=Setup!$C$12,N23>=Setup!$C$12)) -> FALSE | P23: =IF(AND(L23,NOT(O23),E23<>"",F23<>""),1,0) -> 0 | Q23: =IF(L23,D23&"|"&G23,"") -> Felix|David | R23: =IF(L23,G23&"|"&D23,"") -> David|Felix
B24: =IF(L24,J24+1,"") -> 5 | C24: =IF(NOT(L24),"",IF(O24,"Bye",IF(IF(MOD(Setup!$C$12,2)=1,K24,K24+1)>Setup!$C$8,"Next free",IF(MOD(Setup!$C$12,2)=1,K24,K24+1)))) -> 2 | D24: =IF(NOT(L24),"",IF(M24>=Setup!$C$12,"Bye",INDEX(Setup!$C$16:$C$31,M24+1))) -> Grace | G24: =IF(NOT(L24),"",IF(N24>=Setup!$C$12,"Bye",INDEX(Setup!$C$16:$C$31,N24+1))) -> Carla | H24: =IF(OR(NOT(L24),O24,E24="",F24=""),"",IF(E24>F24,D24,IF(F24>E24,G24,"Tie"))) | J24: =IF(Setup!$C$13=0,"",INT(18/((Setup!$C$13+1)/2))) -> 4 | K24: =IF(Setup!$C$13=0,"",MOD(18,(Setup!$C$13+1)/2)) -> 2 | L24: =AND(Setup!$C$13>0,J24<Setup!$C$13) -> TRUE | M24: =IF(NOT(L24),"",IF(K24=0,J24,MOD(J24+K24,Setup!$C$13))) -> 6 | N24: =IF(NOT(L24),"",IF(K24=0,Setup!$C$13,MOD(J24-K24+Setup!$C$13,Setup!$C$13))) -> 2 | O24: =AND(L24,OR(M24>=Setup!$C$12,N24>=Setup!$C$12)) -> FALSE | P24: =IF(AND(L24,NOT(O24),E24<>"",F24<>""),1,0) -> 0 | Q24: =IF(L24,D24&"|"&G24,"") -> Grace|Carla | R24: =IF(L24,G24&"|"&D24,"") -> Carla|Grace
B25: =IF(L25,J25+1,"") -> 5 | C25: =IF(NOT(L25),"",IF(O25,"Bye",IF(IF(MOD(Setup!$C$12,2)=1,K25,K25+1)>Setup!$C$8,"Next free",IF(MOD(Setup!$C$12,2)=1,K25,K25+1)))) -> 3 | D25: =IF(NOT(L25),"",IF(M25>=Setup!$C$12,"Bye",INDEX(Setup!$C$16:$C$31,M25+1))) -> Anna | G25: =IF(NOT(L25),"",IF(N25>=Setup!$C$12,"Bye",INDEX(Setup!$C$16:$C$31,N25+1))) -> Ben | H25: =IF(OR(NOT(L25),O25,E25="",F25=""),"",IF(E25>F25,D25,IF(F25>E25,G25,"Tie"))) | J25: =IF(Setup!$C$13=0,"",INT(19/((Setup!$C$13+1)/2))) -> 4 | K25: =IF(Setup!$C$13=0,"",MOD(19,(Setup!$C$13+1)/2)) -> 3 | L25: =AND(Setup!$C$13>0,J25<Setup!$C$13) -> TRUE | M25: =IF(NOT(L25),"",IF(K25=0,J25,MOD(J25+K25,Setup!$C$13))) -> 0 | N25: =IF(NOT(L25),"",IF(K25=0,Setup!$C$13,MOD(J25-K25+Setup!$C$13,Setup!$C$13))) -> 1 | O25: =AND(L25,OR(M25>=Setup!$C$12,N25>=Setup!$C$12)) -> FALSE | P25: =IF(AND(L25,NOT(O25),E25<>"",F25<>""),1,0) -> 0 | Q25: =IF(L25,D25&"|"&G25,"") -> Anna|Ben | R25: =IF(L25,G25&"|"&D25,"") -> Ben|Anna
B26: =IF(L26,J26+1,"") -> 6 | C26: =IF(NOT(L26),"",IF(O26,"Bye",IF(IF(MOD(Setup!$C$12,2)=1,K26,K26+1)>Setup!$C$8,"Next free",IF(MOD(Setup!$C$12,2)=1,K26,K26+1)))) -> Bye | D26: =IF(NOT(L26),"",IF(M26>=Setup!$C$12,"Bye",INDEX(Setup!$C$16:$C$31,M26+1))) -> Felix | G26: =IF(NOT(L26),"",IF(N26>=Setup!$C$12,"Bye",INDEX(Setup!$C$16:$C$31,N26+1))) -> Bye | H26: =IF(OR(NOT(L26),O26,E26="",F26=""),"",IF(E26>F26,D26,IF(F26>E26,G26,"Tie"))) | J26: =IF(Setup!$C$13=0,"",INT(20/((Setup!$C$13+1)/2))) -> 5 | K26: =IF(Setup!$C$13=0,"",MOD(20,(Setup!$C$13+1)/2)) -> 0 | L26: =AND(Setup!$C$13>0,J26<Setup!$C$13) -> TRUE | M26: =IF(NOT(L26),"",IF(K26=0,J26,MOD(J26+K26,Setup!$C$13))) -> 5 | N26: =IF(NOT(L26),"",IF(K26=0,Setup!$C$13,MOD(J26-K26+Setup!$C$13,Setup!$C$13))) -> 7 | O26: =AND(L26,OR(M26>=Setup!$C$12,N26>=Setup!$C$12)) -> TRUE | P26: =IF(AND(L26,NOT(O26),E26<>"",F26<>""),1,0) -> 0 | Q26: =IF(L26,D26&"|"&G26,"") -> Felix|Bye | R26: =IF(L26,G26&"|"&D26,"") -> Bye|Felix
B27: =IF(L27,J27+1,"") -> 6 | C27: =IF(NOT(L27),"",IF(O27,"Bye",IF(IF(MOD(Setup!$C$12,2)=1,K27,K27+1)>Setup!$C$8,"Next free",IF(MOD(Setup!$C$12,2)=1,K27,K27+1)))) -> 1 | D27: =IF(NOT(L27),"",IF(M27>=Setup!$C$12,"Bye",INDEX(Setup!$C$16:$C$31,M27+1))) -> Grace | G27: =IF(NOT(L27),"",IF(N27>=Setup!$C$12,"Bye",INDEX(Setup!$C$16:$C$31,N27+1))) -> Elena | H27: =IF(OR(NOT(L27),O27,E27="",F27=""),"",IF(E27>F27,D27,IF(F27>E27,G27,"Tie"))) | J27: =IF(Setup!$C$13=0,"",INT(21/((Setup!$C$13+1)/2))) -> 5 | K27: =IF(Setup!$C$13=0,"",MOD(21,(Setup!$C$13+1)/2)) -> 1 | L27: =AND(Setup!$C$13>0,J27<Setup!$C$13) -> TRUE | M27: =IF(NOT(L27),"",IF(K27=0,J27,MOD(J27+K27,Setup!$C$13))) -> 6 | N27: =IF(NOT(L27),"",IF(K27=0,Setup!$C$13,MOD(J27-K27+Setup!$C$13,Setup!$C$13))) -> 4 | O27: =AND(L27,OR(M27>=Setup!$C$12,N27>=Setup!$C$12)) -> FALSE | P27: =IF(AND(L27,NOT(O27),E27<>"",F27<>""),1,0) -> 0 | Q27: =IF(L27,D27&"|"&G27,"") -> Grace|Elena | R27: =IF(L27,G27&"|"&D27,"") -> Elena|Grace
B28: =IF(L28,J28+1,"") -> 6 | C28: =IF(NOT(L28),"",IF(O28,"Bye",IF(IF(MOD(Setup!$C$12,2)=1,K28,K28+1)>Setup!$C$8,"Next free",IF(MOD(Setup!$C$12,2)=1,K28,K28+1)))) -> 2 | D28: =IF(NOT(L28),"",IF(M28>=Setup!$C$12,"Bye",INDEX(Setup!$C$16:$C$31,M28+1))) -> Anna | G28: =IF(NOT(L28),"",IF(N28>=Setup!$C$12,"Bye",INDEX(Setup!$C$16:$C$31,N28+1))) -> David | H28: =IF(OR(NOT(L28),O28,E28="",F28=""),"",IF(E28>F28,D28,IF(F28>E28,G28,"Tie"))) | J28: =IF(Setup!$C$13=0,"",INT(22/((Setup!$C$13+1)/2))) -> 5 | K28: =IF(Setup!$C$13=0,"",MOD(22,(Setup!$C$13+1)/2)) -> 2 | L28: =AND(Setup!$C$13>0,J28<Setup!$C$13) -> TRUE | M28: =IF(NOT(L28),"",IF(K28=0,J28,MOD(J28+K28,Setup!$C$13))) -> 0 | N28: =IF(NOT(L28),"",IF(K28=0,Setup!$C$13,MOD(J28-K28+Setup!$C$13,Setup!$C$13))) -> 3 | O28: =AND(L28,OR(M28>=Setup!$C$12,N28>=Setup!$C$12)) -> FALSE | P28: =IF(AND(L28,NOT(O28),E28<>"",F28<>""),1,0) -> 0 | Q28: =IF(L28,D28&"|"&G28,"") -> Anna|David | R28: =IF(L28,G28&"|"&D28,"") -> David|Anna
B29: =IF(L29,J29+1,"") -> 6 | C29: =IF(NOT(L29),"",IF(O29,"Bye",IF(IF(MOD(Setup!$C$12,2)=1,K29,K29+1)>Setup!$C$8,"Next free",IF(MOD(Setup!$C$12,2)=1,K29,K29+1)))) -> 3 | D29: =IF(NOT(L29),"",IF(M29>=Setup!$C$12,"Bye",INDEX(Setup!$C$16:$C$31,M29+1))) -> Ben | G29: =IF(NOT(L29),"",IF(N29>=Setup!$C$12,"Bye",INDEX(Setup!$C$16:$C$31,N29+1))) -> Carla | H29: =IF(OR(NOT(L29),O29,E29="",F29=""),"",IF(E29>F29,D29,IF(F29>E29,G29,"Tie"))) | J29: =IF(Setup!$C$13=0,"",INT(23/((Setup!$C$13+1)/2))) -> 5 | K29: =IF(Setup!$C$13=0,"",MOD(23,(Setup!$C$13+1)/2)) -> 3 | L29: =AND(Setup!$C$13>0,J29<Setup!$C$13) -> TRUE | M29: =IF(NOT(L29),"",IF(K29=0,J29,MOD(J29+K29,Setup!$C$13))) -> 1 | N29: =IF(NOT(L29),"",IF(K29=0,Setup!$C$13,MOD(J29-K29+Setup!$C$13,Setup!$C$13))) -> 2 | O29: =AND(L29,OR(M29>=Setup!$C$12,N29>=Setup!$C$12)) -> FALSE | P29: =IF(AND(L29,NOT(O29),E29<>"",F29<>""),1,0) -> 0 | Q29: =IF(L29,D29&"|"&G29,"") -> Ben|Carla | R29: =IF(L29,G29&"|"&D29,"") -> Carla|Ben
B30: =IF(L30,J30+1,"") -> 7 | C30: =IF(NOT(L30),"",IF(O30,"Bye",IF(IF(MOD(Setup!$C$12,2)=1,K30,K30+1)>Setup!$C$8,"Next free",IF(MOD(Setup!$C$12,2)=1,K30,K30+1)))) -> Bye | D30: =IF(NOT(L30),"",IF(M30>=Setup!$C$12,"Bye",INDEX(Setup!$C$16:$C$31,M30+1))) -> Grace | G30: =IF(NOT(L30),"",IF(N30>=Setup!$C$12,"Bye",INDEX(Setup!$C$16:$C$31,N30+1))) -> Bye | H30: =IF(OR(NOT(L30),O30,E30="",F30=""),"",IF(E30>F30,D30,IF(F30>E30,G30,"Tie"))) | J30: =IF(Setup!$C$13=0,"",INT(24/((Setup!$C$13+1)/2))) -> 6 | K30: =IF(Setup!$C$13=0,"",MOD(24,(Setup!$C$13+1)/2)) -> 0 | L30: =AND(Setup!$C$13>0,J30<Setup!$C$13) -> TRUE | M30: =IF(NOT(L30),"",IF(K30=0,J30,MOD(J30+K30,Setup!$C$13))) -> 6 | N30: =IF(NOT(L30),"",IF(K30=0,Setup!$C$13,MOD(J30-K30+Setup!$C$13,Setup!$C$13))) -> 7 | O30: =AND(L30,OR(M30>=Setup!$C$12,N30>=Setup!$C$12)) -> TRUE | P30: =IF(AND(L30,NOT(O30),E30<>"",F30<>""),1,0) -> 0 | Q30: =IF(L30,D30&"|"&G30,"") -> Grace|Bye | R30: =IF(L30,G30&"|"&D30,"") -> Bye|Grace
B31: =IF(L31,J31+1,"") -> 7 | C31: =IF(NOT(L31),"",IF(O31,"Bye",IF(IF(MOD(Setup!$C$12,2)=1,K31,K31+1)>Setup!$C$8,"Next free",IF(MOD(Setup!$C$12,2)=1,K31,K31+1)))) -> 1 | D31: =IF(NOT(L31),"",IF(M31>=Setup!$C$12,"Bye",INDEX(Setup!$C$16:$C$31,M31+1))) -> Anna | G31: =IF(NOT(L31),"",IF(N31>=Setup!$C$12,"Bye",INDEX(Setup!$C$16:$C$31,N31+1))) -> Felix | H31: =IF(OR(NOT(L31),O31,E31="",F31=""),"",IF(E31>F31,D31,IF(F31>E31,G31,"Tie"))) | J31: =IF(Setup!$C$13=0,"",INT(25/((Setup!$C$13+1)/2))) -> 6 | K31: =IF(Setup!$C$13=0,"",MOD(25,(Setup!$C$13+1)/2)) -> 1 | L31: =AND(Setup!$C$13>0,J31<Setup!$C$13) -> TRUE | M31: =IF(NOT(L31),"",IF(K31=0,J31,MOD(J31+K31,Setup!$C$13))) -> 0 | N31: =IF(NOT(L31),"",IF(K31=0,Setup!$C$13,MOD(J31-K31+Setup!$C$13,Setup!$C$13))) -> 5 | O31: =AND(L31,OR(M31>=Setup!$C$12,N31>=Setup!$C$12)) -> FALSE | P31: =IF(AND(L31,NOT(O31),E31<>"",F31<>""),1,0) -> 0 | Q31: =IF(L31,D31&"|"&G31,"") -> Anna|Felix | R31: =IF(L31,G31&"|"&D31,"") -> Felix|Anna
B32: =IF(L32,J32+1,"") -> 7 | C32: =IF(NOT(L32),"",IF(O32,"Bye",IF(IF(MOD(Setup!$C$12,2)=1,K32,K32+1)>Setup!$C$8,"Next free",IF(MOD(Setup!$C$12,2)=1,K32,K32+1)))) -> 2 | D32: =IF(NOT(L32),"",IF(M32>=Setup!$C$12,"Bye",INDEX(Setup!$C$16:$C$31,M32+1))) -> Ben | G32: =IF(NOT(L32),"",IF(N32>=Setup!$C$12,"Bye",INDEX(Setup!$C$16:$C$31,N32+1))) -> Elena | H32: =IF(OR(NOT(L32),O32,E32="",F32=""),"",IF(E32>F32,D32,IF(F32>E32,G32,"Tie"))) | J32: =IF(Setup!$C$13=0,"",INT(26/((Setup!$C$13+1)/2))) -> 6 | K32: =IF(Setup!$C$13=0,"",MOD(26,(Setup!$C$13+1)/2)) -> 2 | L32: =AND(Setup!$C$13>0,J32<Setup!$C$13) -> TRUE | M32: =IF(NOT(L32),"",IF(K32=0,J32,MOD(J32+K32,Setup!$C$13))) -> 1 | N32: =IF(NOT(L32),"",IF(K32=0,Setup!$C$13,MOD(J32-K32+Setup!$C$13,Setup!$C$13))) -> 4 | O32: =AND(L32,OR(M32>=Setup!$C$12,N32>=Setup!$C$12)) -> FALSE | P32: =IF(AND(L32,NOT(O32),E32<>"",F32<>""),1,0) -> 0 | Q32: =IF(L32,D32&"|"&G32,"") -> Ben|Elena | R32: =IF(L32,G32&"|"&D32,"") -> Elena|Ben
B33: =IF(L33,J33+1,"") -> 7 | C33: =IF(NOT(L33),"",IF(O33,"Bye",IF(IF(MOD(Setup!$C$12,2)=1,K33,K33+1)>Setup!$C$8,"Next free",IF(MOD(Setup!$C$12,2)=1,K33,K33+1)))) -> 3 | D33: =IF(NOT(L33),"",IF(M33>=Setup!$C$12,"Bye",INDEX(Setup!$C$16:$C$31,M33+1))) -> Carla | G33: =IF(NOT(L33),"",IF(N33>=Setup!$C$12,"Bye",INDEX(Setup!$C$16:$C$31,N33+1))) -> David | H33: =IF(OR(NOT(L33),O33,E33="",F33=""),"",IF(E33>F33,D33,IF(F33>E33,G33,"Tie"))) | J33: =IF(Setup!$C$13=0,"",INT(27/((Setup!$C$13+1)/2))) -> 6 | K33: =IF(Setup!$C$13=0,"",MOD(27,(Setup!$C$13+1)/2)) -> 3 | L33: =AND(Setup!$C$13>0,J33<Setup!$C$13) -> TRUE | M33: =IF(NOT(L33),"",IF(K33=0,J33,MOD(J33+K33,Setup!$C$13))) -> 2 | N33: =IF(NOT(L33),"",IF(K33=0,Setup!$C$13,MOD(J33-K33+Setup!$C$13,Setup!$C$13))) -> 3 | O33: =AND(L33,OR(M33>=Setup!$C$12,N33>=Setup!$C$12)) -> FALSE | P33: =IF(AND(L33,NOT(O33),E33<>"",F33<>""),1,0) -> 0 | Q33: =IF(L33,D33&"|"&G33,"") -> Carla|David | R33: =IF(L33,G33&"|"&D33,"") -> David|Carla
B34: =IF(L34,J34+1,"") | C34: =IF(NOT(L34),"",IF(O34,"Bye",IF(IF(MOD(Setup!$C$12,2)=1,K34,K34+1)>Setup!$C$8,"Next free",IF(MOD(Setup!$C$12,2)=1,K34,K34+1)))) | D34: =IF(NOT(L34),"",IF(M34>=Setup!$C$12,"Bye",INDEX(Setup!$C$16:$C$31,M34+1))) | G34: =IF(NOT(L34),"",IF(N34>=Setup!$C$12,"Bye",INDEX(Setup!$C$16:$C$31,N34+1))) | H34: =IF(OR(NOT(L34),O34,E34="",F34=""),"",IF(E34>F34,D34,IF(F34>E34,G34,"Tie"))) | J34: =IF(Setup!$C$13=0,"",INT(28/((Setup!$C$13+1)/2))) -> 7 | K34: =IF(Setup!$C$13=0,"",MOD(28,(Setup!$C$13+1)/2)) -> 0 | L34: =AND(Setup!$C$13>0,J34<Setup!$C$13) -> FALSE | M34: =IF(NOT(L34),"",IF(K34=0,J34,MOD(J34+K34,Setup!$C$13))) | N34: =IF(NOT(L34),"",IF(K34=0,Setup!$C$13,MOD(J34-K34+Setup!$C$13,Setup!$C$13))) | O34: =AND(L34,OR(M34>=Setup!$C$12,N34>=Setup!$C$12)) -> FALSE | P34: =IF(AND(L34,NOT(O34),E34<>"",F34<>""),1,0) -> 0 | Q34: =IF(L34,D34&"|"&G34,"") | R34: =IF(L34,G34&"|"&D34,"")
B35: =IF(L35,J35+1,"") | C35: =IF(NOT(L35),"",IF(O35,"Bye",IF(IF(MOD(Setup!$C$12,2)=1,K35,K35+1)>Setup!$C$8,"Next free",IF(MOD(Setup!$C$12,2)=1,K35,K35+1)))) | D35: =IF(NOT(L35),"",IF(M35>=Setup!$C$12,"Bye",INDEX(Setup!$C$16:$C$31,M35+1))) | G35: =IF(NOT(L35),"",IF(N35>=Setup!$C$12,"Bye",INDEX(Setup!$C$16:$C$31,N35+1))) | H35: =IF(OR(NOT(L35),O35,E35="",F35=""),"",IF(E35>F35,D35,IF(F35>E35,G35,"Tie"))) | J35: =IF(Setup!$C$13=0,"",INT(29/((Setup!$C$13+1)/2))) -> 7 | K35: =IF(Setup!$C$13=0,"",MOD(29,(Setup!$C$13+1)/2)) -> 1 | L35: =AND(Setup!$C$13>0,J35<Setup!$C$13) -> FALSE | M35: =IF(NOT(L35),"",IF(K35=0,J35,MOD(J35+K35,Setup!$C$13))) | N35: =IF(NOT(L35),"",IF(K35=0,Setup!$C$13,MOD(J35-K35+Setup!$C$13,Setup!$C$13))) | O35: =AND(L35,OR(M35>=Setup!$C$12,N35>=Setup!$C$12)) -> FALSE | P35: =IF(AND(L35,NOT(O35),E35<>"",F35<>""),1,0) -> 0 | Q35: =IF(L35,D35&"|"&G35,"") | R35: =IF(L35,G35&"|"&D35,"")
B36: =IF(L36,J36+1,"") | C36: =IF(NOT(L36),"",IF(O36,"Bye",IF(IF(MOD(Setup!$C$12,2)=1,K36,K36+1)>Setup!$C$8,"Next free",IF(MOD(Setup!$C$12,2)=1,K36,K36+1)))) | D36: =IF(NOT(L36),"",IF(M36>=Setup!$C$12,"Bye",INDEX(Setup!$C$16:$C$31,M36+1))) | G36: =IF(NOT(L36),"",IF(N36>=Setup!$C$12,"Bye",INDEX(Setup!$C$16:$C$31,N36+1))) | H36: =IF(OR(NOT(L36),O36,E36="",F36=""),"",IF(E36>F36,D36,IF(F36>E36,G36,"Tie"))) | J36: =IF(Setup!$C$13=0,"",INT(30/((Setup!$C$13+1)/2))) -> 7 | K36: =IF(Setup!$C$13=0,"",MOD(30,(Setup!$C$13+1)/2)) -> 2 | L36: =AND(Setup!$C$13>0,J36<Setup!$C$13) -> FALSE | M36: =IF(NOT(L36),"",IF(K36=0,J36,MOD(J36+K36,Setup!$C$13))) | N36: =IF(NOT(L36),"",IF(K36=0,Setup!$C$13,MOD(J36-K36+Setup!$C$13,Setup!$C$13))) | O36: =AND(L36,OR(M36>=Setup!$C$12,N36>=Setup!$C$12)) -> FALSE | P36: =IF(AND(L36,NOT(O36),E36<>"",F36<>""),1,0) -> 0 | Q36: =IF(L36,D36&"|"&G36,"") | R36: =IF(L36,G36&"|"&D36,"")
B37: =IF(L37,J37+1,"") | C37: =IF(NOT(L37),"",IF(O37,"Bye",IF(IF(MOD(Setup!$C$12,2)=1,K37,K37+1)>Setup!$C$8,"Next free",IF(MOD(Setup!$C$12,2)=1,K37,K37+1)))) | D37: =IF(NOT(L37),"",IF(M37>=Setup!$C$12,"Bye",INDEX(Setup!$C$16:$C$31,M37+1))) | G37: =IF(NOT(L37),"",IF(N37>=Setup!$C$12,"Bye",INDEX(Setup!$C$16:$C$31,N37+1))) | H37: =IF(OR(NOT(L37),O37,E37="",F37=""),"",IF(E37>F37,D37,IF(F37>E37,G37,"Tie"))) | J37: =IF(Setup!$C$13=0,"",INT(31/((Setup!$C$13+1)/2))) -> 7 | K37: =IF(Setup!$C$13=0,"",MOD(31,(Setup!$C$13+1)/2)) -> 3 | L37: =AND(Setup!$C$13>0,J37<Setup!$C$13) -> FALSE | M37: =IF(NOT(L37),"",IF(K37=0,J37,MOD(J37+K37,Setup!$C$13))) | N37: =IF(NOT(L37),"",IF(K37=0,Setup!$C$13,MOD(J37-K37+Setup!$C$13,Setup!$C$13))) | O37: =AND(L37,OR(M37>=Setup!$C$12,N37>=Setup!$C$12)) -> FALSE | P37: =IF(AND(L37,NOT(O37),E37<>"",F37<>""),1,0) -> 0 | Q37: =IF(L37,D37&"|"&G37,"") | R37: =IF(L37,G37&"|"&D37,"")
B38: =IF(L38,J38+1,"") | C38: =IF(NOT(L38),"",IF(O38,"Bye",IF(IF(MOD(Setup!$C$12,2)=1,K38,K38+1)>Setup!$C$8,"Next free",IF(MOD(Setup!$C$12,2)=1,K38,K38+1)))) | D38: =IF(NOT(L38),"",IF(M38>=Setup!$C$12,"Bye",INDEX(Setup!$C$16:$C$31,M38+1))) | G38: =IF(NOT(L38),"",IF(N38>=Setup!$C$12,"Bye",INDEX(Setup!$C$16:$C$31,N38+1))) | H38: =IF(OR(NOT(L38),O38,E38="",F38=""),"",IF(E38>F38,D38,IF(F38>E38,G38,"Tie"))) | J38: =IF(Setup!$C$13=0,"",INT(32/((Setup!$C$13+1)/2))) -> 8 | K38: =IF(Setup!$C$13=0,"",MOD(32,(Setup!$C$13+1)/2)) -> 0 | L38: =AND(Setup!$C$13>0,J38<Setup!$C$13) -> FALSE | M38: =IF(NOT(L38),"",IF(K38=0,J38,MOD(J38+K38,Setup!$C$13))) | N38: =IF(NOT(L38),"",IF(K38=0,Setup!$C$13,MOD(J38-K38+Setup!$C$13,Setup!$C$13))) | O38: =AND(L38,OR(M38>=Setup!$C$12,N38>=Setup!$C$12)) -> FALSE | P38: =IF(AND(L38,NOT(O38),E38<>"",F38<>""),1,0) -> 0 | Q38: =IF(L38,D38&"|"&G38,"") | R38: =IF(L38,G38&"|"&D38,"")
B39: =IF(L39,J39+1,"") | C39: =IF(NOT(L39),"",IF(O39,"Bye",IF(IF(MOD(Setup!$C$12,2)=1,K39,K39+1)>Setup!$C$8,"Next free",IF(MOD(Setup!$C$12,2)=1,K39,K39+1)))) | D39: =IF(NOT(L39),"",IF(M39>=Setup!$C$12,"Bye",INDEX(Setup!$C$16:$C$31,M39+1))) | G39: =IF(NOT(L39),"",IF(N39>=Setup!$C$12,"Bye",INDEX(Setup!$C$16:$C$31,N39+1))) | H39: =IF(OR(NOT(L39),O39,E39="",F39=""),"",IF(E39>F39,D39,IF(F39>E39,G39,"Tie"))) | J39: =IF(Setup!$C$13=0,"",INT(33/((Setup!$C$13+1)/2))) -> 8 | K39: =IF(Setup!$C$13=0,"",MOD(33,(Setup!$C$13+1)/2)) -> 1 | L39: =AND(Setup!$C$13>0,J39<Setup!$C$13) -> FALSE | M39: =IF(NOT(L39),"",IF(K39=0,J39,MOD(J39+K39,Setup!$C$13))) | N39: =IF(NOT(L39),"",IF(K39=0,Setup!$C$13,MOD(J39-K39+Setup!$C$13,Setup!$C$13))) | O39: =AND(L39,OR(M39>=Setup!$C$12,N39>=Setup!$C$12)) -> FALSE | P39: =IF(AND(L39,NOT(O39),E39<>"",F39<>""),1,0) -> 0 | Q39: =IF(L39,D39&"|"&G39,"") | R39: =IF(L39,G39&"|"&D39,"")
B40: =IF(L40,J40+1,"") | C40: =IF(NOT(L40),"",IF(O40,"Bye",IF(IF(MOD(Setup!$C$12,2)=1,K40,K40+1)>Setup!$C$8,"Next free",IF(MOD(Setup!$C$12,2)=1,K40,K40+1)))) | D40: =IF(NOT(L40),"",IF(M40>=Setup!$C$12,"Bye",INDEX(Setup!$C$16:$C$31,M40+1))) | G40: =IF(NOT(L40),"",IF(N40>=Setup!$C$12,"Bye",INDEX(Setup!$C$16:$C$31,N40+1))) | H40: =IF(OR(NOT(L40),O40,E40="",F40=""),"",IF(E40>F40,D40,IF(F40>E40,G40,"Tie"))) | J40: =IF(Setup!$C$13=0,"",INT(34/((Setup!$C$13+1)/2))) -> 8 | K40: =IF(Setup!$C$13=0,"",MOD(34,(Setup!$C$13+1)/2)) -> 2 | L40: =AND(Setup!$C$13>0,J40<Setup!$C$13) -> FALSE | M40: =IF(NOT(L40),"",IF(K40=0,J40,MOD(J40+K40,Setup!$C$13))) | N40: =IF(NOT(L40),"",IF(K40=0,Setup!$C$13,MOD(J40-K40+Setup!$C$13,Setup!$C$13))) | O40: =AND(L40,OR(M40>=Setup!$C$12,N40>=Setup!$C$12)) -> FALSE | P40: =IF(AND(L40,NOT(O40),E40<>"",F40<>""),1,0) -> 0 | Q40: =IF(L40,D40&"|"&G40,"") | R40: =IF(L40,G40&"|"&D40,"")
B41: =IF(L41,J41+1,"") | C41: =IF(NOT(L41),"",IF(O41,"Bye",IF(IF(MOD(Setup!$C$12,2)=1,K41,K41+1)>Setup!$C$8,"Next free",IF(MOD(Setup!$C$12,2)=1,K41,K41+1)))) | D41: =IF(NOT(L41),"",IF(M41>=Setup!$C$12,"Bye",INDEX(Setup!$C$16:$C$31,M41+1))) | G41: =IF(NOT(L41),"",IF(N41>=Setup!$C$12,"Bye",INDEX(Setup!$C$16:$C$31,N41+1))) | H41: =IF(OR(NOT(L41),O41,E41="",F41=""),"",IF(E41>F41,D41,IF(F41>E41,G41,"Tie"))) | J41: =IF(Setup!$C$13=0,"",INT(35/((Setup!$C$13+1)/2))) -> 8 | K41: =IF(Setup!$C$13=0,"",MOD(35,(Setup!$C$13+1)/2)) -> 3 | L41: =AND(Setup!$C$13>0,J41<Setup!$C$13) -> FALSE | M41: =IF(NOT(L41),"",IF(K41=0,J41,MOD(J41+K41,Setup!$C$13))) | N41: =IF(NOT(L41),"",IF(K41=0,Setup!$C$13,MOD(J41-K41+Setup!$C$13,Setup!$C$13))) | O41: =AND(L41,OR(M41>=Setup!$C$12,N41>=Setup!$C$12)) -> FALSE | P41: =IF(AND(L41,NOT(O41),E41<>"",F41<>""),1,0) -> 0 | Q41: =IF(L41,D41&"|"&G41,"") | R41: =IF(L41,G41&"|"&D41,"")
B42: =IF(L42,J42+1,"") | C42: =IF(NOT(L42),"",IF(O42,"Bye",IF(IF(MOD(Setup!$C$12,2)=1,K42,K42+1)>Setup!$C$8,"Next free",IF(MOD(Setup!$C$12,2)=1,K42,K42+1)))) | D42: =IF(NOT(L42),"",IF(M42>=Setup!$C$12,"Bye",INDEX(Setup!$C$16:$C$31,M42+1))) | G42: =IF(NOT(L42),"",IF(N42>=Setup!$C$12,"Bye",INDEX(Setup!$C$16:$C$31,N42+1))) | H42: =IF(OR(NOT(L42),O42,E42="",F42=""),"",IF(E42>F42,D42,IF(F42>E42,G42,"Tie"))) | J42: =IF(Setup!$C$13=0,"",INT(36/((Setup!$C$13+1)/2))) -> 9 | K42: =IF(Setup!$C$13=0,"",MOD(36,(Setup!$C$13+1)/2)) -> 0 | L42: =AND(Setup!$C$13>0,J42<Setup!$C$13) -> FALSE | M42: =IF(NOT(L42),"",IF(K42=0,J42,MOD(J42+K42,Setup!$C$13))) | N42: =IF(NOT(L42),"",IF(K42=0,Setup!$C$13,MOD(J42-K42+Setup!$C$13,Setup!$C$13))) | O42: =AND(L42,OR(M42>=Setup!$C$12,N42>=Setup!$C$12)) -> FALSE | P42: =IF(AND(L42,NOT(O42),E42<>"",F42<>""),1,0) -> 0 | Q42: =IF(L42,D42&"|"&G42,"") | R42: =IF(L42,G42&"|"&D42,"")
...

Sheet Standings
B2: Standings
B3: POINTS, THEN GAME DIFFERENCE, THEN GAMES WON
B6: Pos | C6: Player / team | D6: Played | E6: Won | F6: Tied | G6: Lost | H6: Games for | I6: Games against | J6: Game diff | K6: Points
B7: =IF(W7="","",ROW()-6) -> 1 | C7: =IF(W7="","",INDEX($M$7:$M$22,W7)) -> Ben | D7: =IF(W7="","",INDEX($N$7:$N$22,W7)) -> 2 | E7: =IF(W7="","",INDEX($O$7:$O$22,W7)) -> 2 | F7: =IF(W7="","",INDEX($P$7:$P$22,W7)) -> 0 | G7: =IF(W7="","",INDEX($Q$7:$Q$22,W7)) -> 0 | H7: =IF(W7="","",INDEX($R$7:$R$22,W7)) -> 12 | I7: =IF(W7="","",INDEX($S$7:$S$22,W7)) -> 6 | J7: =IF(W7="","",INDEX($T$7:$T$22,W7)) -> 6 | K7: =IF(W7="","",INDEX($U$7:$U$22,W7)) -> 2 | M7: =IF(Setup!$C$16="","",Setup!$C$16) -> Anna | N7: =IF(M7="","",SUMIF(Schedule!$D$6:$D$125,M7,Schedule!$P$6:$P$125)+SUMIF(Schedule!$G$6:$G$125,M7,Schedule!$P$6:$P$125)) -> 2 | O7: =IF(M7="","",COUNTIF(Schedule!$H$6:$H$125,M7)) -> 0 | P7: =IF(M7="","",COUNTIFS(Schedule!$D$6:$D$125,M7,Schedule!$H$6:$H$125,"Tie")+COUNTIFS(Schedule!$G$6:$G$125,M7,Schedule!$H$6:$H$125,"Tie")) -> 1 | Q7: =IF(M7="","",N7-O7-P7) -> 1 | R7: =IF(M7="","",SUMIFS(Schedule!$E$6:$E$125,Schedule!$D$6:$D$125,M7,Schedule!$P$6:$P$125,1)+SUMIFS(Schedule!$F$6:$F$125,Schedule!$G$6:$G$125,M7,Schedule!$P$6:$P$125,1)) -> 9 | S7: =IF(M7="","",SUMIFS(Schedule!$F$6:$F$125,Schedule!$D$6:$D$125,M7,Schedule!$P$6:$P$125,1)+SUMIFS(Schedule!$E$6:$E$125,Schedule!$G$6:$G$125,M7,Schedule!$P$6:$P$125,1)) -> 11 | T7: =IF(M7="","",R7-S7) -> -2 | U7: =IF(M7="","",O7*Setup!$C$9+P7*Setup!$C$10) -> 0.5 | V7: =IF(M7="","",U7*1000000+(T7+1000)*1000+R7+(100-ROW())/1000) -> 1498009.1 | W7: =IF(ROW()-6>COUNT($V$7:$V$22),"",MATCH(LARGE($V$7:$V$22,ROW()-6),$V$7:$V$22,0)) -> 2
B8: =IF(W8="","",ROW()-6) -> 2 | C8: =IF(W8="","",INDEX($M$7:$M$22,W8)) -> Felix | D8: =IF(W8="","",INDEX($N$7:$N$22,W8)) -> 3 | E8: =IF(W8="","",INDEX($O$7:$O$22,W8)) -> 2 | F8: =IF(W8="","",INDEX($P$7:$P$22,W8)) -> 0 | G8: =IF(W8="","",INDEX($Q$7:$Q$22,W8)) -> 1 | H8: =IF(W8="","",INDEX($R$7:$R$22,W8)) -> 13 | I8: =IF(W8="","",INDEX($S$7:$S$22,W8)) -> 10 | J8: =IF(W8="","",INDEX($T$7:$T$22,W8)) -> 3 | K8: =IF(W8="","",INDEX($U$7:$U$22,W8)) -> 2 | M8: =IF(Setup!$C$17="","",Setup!$C$17) -> Ben | N8: =IF(M8="","",SUMIF(Schedule!$D$6:$D$125,M8,Schedule!$P$6:$P$125)+SUMIF(Schedule!$G$6:$G$125,M8,Schedule!$P$6:$P$125)) -> 2 | O8: =IF(M8="","",COUNTIF(Schedule!$H$6:$H$125,M8)) -> 2 | P8: =IF(M8="","",COUNTIFS(Schedule!$D$6:$D$125,M8,Schedule!$H$6:$H$125,"Tie")+COUNTIFS(Schedule!$G$6:$G$125,M8,Schedule!$H$6:$H$125,"Tie")) -> 0 | Q8: =IF(M8="","",N8-O8-P8) -> 0 | R8: =IF(M8="","",SUMIFS(Schedule!$E$6:$E$125,Schedule!$D$6:$D$125,M8,Schedule!$P$6:$P$125,1)+SUMIFS(Schedule!$F$6:$F$125,Schedule!$G$6:$G$125,M8,Schedule!$P$6:$P$125,1)) -> 12 | S8: =IF(M8="","",SUMIFS(Schedule!$F$6:$F$125,Schedule!$D$6:$D$125,M8,Schedule!$P$6:$P$125,1)+SUMIFS(Schedule!$E$6:$E$125,Schedule!$G$6:$G$125,M8,Schedule!$P$6:$P$125,1)) -> 6 | T8: =IF(M8="","",R8-S8) -> 6 | U8: =IF(M8="","",O8*Setup!$C$9+P8*Setup!$C$10) -> 2 | V8: =IF(M8="","",U8*1000000+(T8+1000)*1000+R8+(100-ROW())/1000) -> 3006012.1 | W8: =IF(ROW()-6>COUNT($V$7:$V$22),"",MATCH(LARGE($V$7:$V$22,ROW()-6),$V$7:$V$22,0)) -> 6
B9: =IF(W9="","",ROW()-6) -> 3 | C9: =IF(W9="","",INDEX($M$7:$M$22,W9)) -> Elena | D9: =IF(W9="","",INDEX($N$7:$N$22,W9)) -> 3 | E9: =IF(W9="","",INDEX($O$7:$O$22,W9)) -> 1 | F9: =IF(W9="","",INDEX($P$7:$P$22,W9)) -> 1 | G9: =IF(W9="","",INDEX($Q$7:$Q$22,W9)) -> 1 | H9: =IF(W9="","",INDEX($R$7:$R$22,W9)) -> 13 | I9: =IF(W9="","",INDEX($S$7:$S$22,W9)) -> 12 | J9: =IF(W9="","",INDEX($T$7:$T$22,W9)) -> 1 | K9: =IF(W9="","",INDEX($U$7:$U$22,W9)) -> 1.5 | M9: =IF(Setup!$C$18="","",Setup!$C$18) -> Carla | N9: =IF(M9="","",SUMIF(Schedule!$D$6:$D$125,M9,Schedule!$P$6:$P$125)+SUMIF(Schedule!$G$6:$G$125,M9,Schedule!$P$6:$P$125)) -> 2 | O9: =IF(M9="","",COUNTIF(Schedule!$H$6:$H$125,M9)) -> 1 | P9: =IF(M9="","",COUNTIFS(Schedule!$D$6:$D$125,M9,Schedule!$H$6:$H$125,"Tie")+COUNTIFS(Schedule!$G$6:$G$125,M9,Schedule!$H$6:$H$125,"Tie")) -> 0 | Q9: =IF(M9="","",N9-O9-P9) -> 1 | R9: =IF(M9="","",SUMIFS(Schedule!$E$6:$E$125,Schedule!$D$6:$D$125,M9,Schedule!$P$6:$P$125,1)+SUMIFS(Schedule!$F$6:$F$125,Schedule!$G$6:$G$125,M9,Schedule!$P$6:$P$125,1)) -> 10 | S9: =IF(M9="","",SUMIFS(Schedule!$F$6:$F$125,Schedule!$D$6:$D$125,M9,Schedule!$P$6:$P$125,1)+SUMIFS(Schedule!$E$6:$E$125,Schedule!$G$6:$G$125,M9,Schedule!$P$6:$P$125,1)) -> 10 | T9: =IF(M9="","",R9-S9) -> 0 | U9: =IF(M9="","",O9*Setup!$C$9+P9*Setup!$C$10) -> 1 | V9: =IF(M9="","",U9*1000000+(T9+1000)*1000+R9+(100-ROW())/1000) -> 2000010.1 | W9: =IF(ROW()-6>COUNT($V$7:$V$22),"",MATCH(LARGE($V$7:$V$22,ROW()-6),$V$7:$V$22,0)) -> 5
B10: =IF(W10="","",ROW()-6) -> 4 | C10: =IF(W10="","",INDEX($M$7:$M$22,W10)) -> David | D10: =IF(W10="","",INDEX($N$7:$N$22,W10)) -> 3 | E10: =IF(W10="","",INDEX($O$7:$O$22,W10)) -> 1 | F10: =IF(W10="","",INDEX($P$7:$P$22,W10)) -> 0 | G10: =IF(W10="","",INDEX($Q$7:$Q$22,W10)) -> 2 | H10: =IF(W10="","",INDEX($R$7:$R$22,W10)) -> 14 | I10: =IF(W10="","",INDEX($S$7:$S$22,W10)) -> 14 | J10: =IF(W10="","",INDEX($T$7:$T$22,W10)) -> 0 | K10: =IF(W10="","",INDEX($U$7:$U$22,W10)) -> 1 | M10: =IF(Setup!$C$19="","",Setup!$C$19) -> David | N10: =IF(M10="","",SUMIF(Schedule!$D$6:$D$125,M10,Schedule!$P$6:$P$125)+SUMIF(Schedule!$G$6:$G$125,M10,Schedule!$P$6:$P$125)) -> 3 | O10: =IF(M10="","",COUNTIF(Schedule!$H$6:$H$125,M10)) -> 1 | P10: =IF(M10="","",COUNTIFS(Schedule!$D$6:$D$125,M10,Schedule!$H$6:$H$125,"Tie")+COUNTIFS(Schedule!$G$6:$G$125,M10,Schedule!$H$6:$H$125,"Tie")) -> 0 | Q10: =IF(M10="","",N10-O10-P10) -> 2 | R10: =IF(M10="","",SUMIFS(Schedule!$E$6:$E$125,Schedule!$D$6:$D$125,M10,Schedule!$P$6:$P$125,1)+SUMIFS(Schedule!$F$6:$F$125,Schedule!$G$6:$G$125,M10,Schedule!$P$6:$P$125,1)) -> 14 | S10: =IF(M10="","",SUMIFS(Schedule!$F$6:$F$125,Schedule!$D$6:$D$125,M10,Schedule!$P$6:$P$125,1)+SUMIFS(Schedule!$E$6:$E$125,Schedule!$G$6:$G$125,M10,Schedule!$P$6:$P$125,1)) -> 14 | T10: =IF(M10="","",R10-S10) -> 0 | U10: =IF(M10="","",O10*Setup!$C$9+P10*Setup!$C$10) -> 1 | V10: =IF(M10="","",U10*1000000+(T10+1000)*1000+R10+(100-ROW())/1000) -> 2000014.1 | W10: =IF(ROW()-6>COUNT($V$7:$V$22),"",MATCH(LARGE($V$7:$V$22,ROW()-6),$V$7:$V$22,0)) -> 4
B11: =IF(W11="","",ROW()-6) -> 5 | C11: =IF(W11="","",INDEX($M$7:$M$22,W11)) -> Carla | D11: =IF(W11="","",INDEX($N$7:$N$22,W11)) -> 2 | E11: =IF(W11="","",INDEX($O$7:$O$22,W11)) -> 1 | F11: =IF(W11="","",INDEX($P$7:$P$22,W11)) -> 0 | G11: =IF(W11="","",INDEX($Q$7:$Q$22,W11)) -> 1 | H11: =IF(W11="","",INDEX($R$7:$R$22,W11)) -> 10 | I11: =IF(W11="","",INDEX($S$7:$S$22,W11)) -> 10 | J11: =IF(W11="","",INDEX($T$7:$T$22,W11)) -> 0 | K11: =IF(W11="","",INDEX($U$7:$U$22,W11)) -> 1 | M11: =IF(Setup!$C$20="","",Setup!$C$20) -> Elena | N11: =IF(M11="","",SUMIF(Schedule!$D$6:$D$125,M11,Schedule!$P$6:$P$125)+SUMIF(Schedule!$G$6:$G$125,M11,Schedule!$P$6:$P$125)) -> 3 | O11: =IF(M11="","",COUNTIF(Schedule!$H$6:$H$125,M11)) -> 1 | P11: =IF(M11="","",COUNTIFS(Schedule!$D$6:$D$125,M11,Schedule!$H$6:$H$125,"Tie")+COUNTIFS(Schedule!$G$6:$G$125,M11,Schedule!$H$6:$H$125,"Tie")) -> 1 | Q11: =IF(M11="","",N11-O11-P11) -> 1 | R11: =IF(M11="","",SUMIFS(Schedule!$E$6:$E$125,Schedule!$D$6:$D$125,M11,Schedule!$P$6:$P$125,1)+SUMIFS(Schedule!$F$6:$F$125,Schedule!$G$6:$G$125,M11,Schedule!$P$6:$P$125,1)) -> 13 | S11: =IF(M11="","",SUMIFS(Schedule!$F$6:$F$125,Schedule!$D$6:$D$125,M11,Schedule!$P$6:$P$125,1)+SUMIFS(Schedule!$E$6:$E$125,Schedule!$G$6:$G$125,M11,Schedule!$P$6:$P$125,1)) -> 12 | T11: =IF(M11="","",R11-S11) -> 1 | U11: =IF(M11="","",O11*Setup!$C$9+P11*Setup!$C$10) -> 1.5 | V11: =IF(M11="","",U11*1000000+(T11+1000)*1000+R11+(100-ROW())/1000) -> 2501013.1 | W11: =IF(ROW()-6>COUNT($V$7:$V$22),"",MATCH(LARGE($V$7:$V$22,ROW()-6),$V$7:$V$22,0)) -> 3
B12: =IF(W12="","",ROW()-6) -> 6 | C12: =IF(W12="","",INDEX($M$7:$M$22,W12)) -> Grace | D12: =IF(W12="","",INDEX($N$7:$N$22,W12)) -> 3 | E12: =IF(W12="","",INDEX($O$7:$O$22,W12)) -> 1 | F12: =IF(W12="","",INDEX($P$7:$P$22,W12)) -> 0 | G12: =IF(W12="","",INDEX($Q$7:$Q$22,W12)) -> 2 | H12: =IF(W12="","",INDEX($R$7:$R$22,W12)) -> 9 | I12: =IF(W12="","",INDEX($S$7:$S$22,W12)) -> 17 | J12: =IF(W12="","",INDEX($T$7:$T$22,W12)) -> -8 | K12: =IF(W12="","",INDEX($U$7:$U$22,W12)) -> 1 | M12: =IF(Setup!$C$21="","",Setup!$C$21) -> Felix | N12: =IF(M12="","",SUMIF(Schedule!$D$6:$D$125,M12,Schedule!$P$6:$P$125)+SUMIF(Schedule!$G$6:$G$125,M12,Schedule!$P$6:$P$125)) -> 3 | O12: =IF(M12="","",COUNTIF(Schedule!$H$6:$H$125,M12)) -> 2 | P12: =IF(M12="","",COUNTIFS(Schedule!$D$6:$D$125,M12,Schedule!$H$6:$H$125,"Tie")+COUNTIFS(Schedule!$G$6:$G$125,M12,Schedule!$H$6:$H$125,"Tie")) -> 0 | Q12: =IF(M12="","",N12-O12-P12) -> 1 | R12: =IF(M12="","",SUMIFS(Schedule!$E$6:$E$125,Schedule!$D$6:$D$125,M12,Schedule!$P$6:$P$125,1)+SUMIFS(Schedule!$F$6:$F$125,Schedule!$G$6:$G$125,M12,Schedule!$P$6:$P$125,1)) -> 13 | S12: =IF(M12="","",SUMIFS(Schedule!$F$6:$F$125,Schedule!$D$6:$D$125,M12,Schedule!$P$6:$P$125,1)+SUMIFS(Schedule!$E$6:$E$125,Schedule!$G$6:$G$125,M12,Schedule!$P$6:$P$125,1)) -> 10 | T12: =IF(M12="","",R12-S12) -> 3 | U12: =IF(M12="","",O12*Setup!$C$9+P12*Setup!$C$10) -> 2 | V12: =IF(M12="","",U12*1000000+(T12+1000)*1000+R12+(100-ROW())/1000) -> 3003013.1 | W12: =IF(ROW()-6>COUNT($V$7:$V$22),"",MATCH(LARGE($V$7:$V$22,ROW()-6),$V$7:$V$22,0)) -> 7
B13: =IF(W13="","",ROW()-6) -> 7 | C13: =IF(W13="","",INDEX($M$7:$M$22,W13)) -> Anna | D13: =IF(W13="","",INDEX($N$7:$N$22,W13)) -> 2 | E13: =IF(W13="","",INDEX($O$7:$O$22,W13)) -> 0 | F13: =IF(W13="","",INDEX($P$7:$P$22,W13)) -> 1 | G13: =IF(W13="","",INDEX($Q$7:$Q$22,W13)) -> 1 | H13: =IF(W13="","",INDEX($R$7:$R$22,W13)) -> 9 | I13: =IF(W13="","",INDEX($S$7:$S$22,W13)) -> 11 | J13: =IF(W13="","",INDEX($T$7:$T$22,W13)) -> -2 | K13: =IF(W13="","",INDEX($U$7:$U$22,W13)) -> 0.5 | M13: =IF(Setup!$C$22="","",Setup!$C$22) -> Grace | N13: =IF(M13="","",SUMIF(Schedule!$D$6:$D$125,M13,Schedule!$P$6:$P$125)+SUMIF(Schedule!$G$6:$G$125,M13,Schedule!$P$6:$P$125)) -> 3 | O13: =IF(M13="","",COUNTIF(Schedule!$H$6:$H$125,M13)) -> 1 | P13: =IF(M13="","",COUNTIFS(Schedule!$D$6:$D$125,M13,Schedule!$H$6:$H$125,"Tie")+COUNTIFS(Schedule!$G$6:$G$125,M13,Schedule!$H$6:$H$125,"Tie")) -> 0 | Q13: =IF(M13="","",N13-O13-P13) -> 2 | R13: =IF(M13="","",SUMIFS(Schedule!$E$6:$E$125,Schedule!$D$6:$D$125,M13,Schedule!$P$6:$P$125,1)+SUMIFS(Schedule!$F$6:$F$125,Schedule!$G$6:$G$125,M13,Schedule!$P$6:$P$125,1)) -> 9 | S13: =IF(M13="","",SUMIFS(Schedule!$F$6:$F$125,Schedule!$D$6:$D$125,M13,Schedule!$P$6:$P$125,1)+SUMIFS(Schedule!$E$6:$E$125,Schedule!$G$6:$G$125,M13,Schedule!$P$6:$P$125,1)) -> 17 | T13: =IF(M13="","",R13-S13) -> -8 | U13: =IF(M13="","",O13*Setup!$C$9+P13*Setup!$C$10) -> 1 | V13: =IF(M13="","",U13*1000000+(T13+1000)*1000+R13+(100-ROW())/1000) -> 1992009.1 | W13: =IF(ROW()-6>COUNT($V$7:$V$22),"",MATCH(LARGE($V$7:$V$22,ROW()-6),$V$7:$V$22,0)) -> 1
B14: =IF(W14="","",ROW()-6) | C14: =IF(W14="","",INDEX($M$7:$M$22,W14)) | D14: =IF(W14="","",INDEX($N$7:$N$22,W14)) | E14: =IF(W14="","",INDEX($O$7:$O$22,W14)) | F14: =IF(W14="","",INDEX($P$7:$P$22,W14)) | G14: =IF(W14="","",INDEX($Q$7:$Q$22,W14)) | H14: =IF(W14="","",INDEX($R$7:$R$22,W14)) | I14: =IF(W14="","",INDEX($S$7:$S$22,W14)) | J14: =IF(W14="","",INDEX($T$7:$T$22,W14)) | K14: =IF(W14="","",INDEX($U$7:$U$22,W14)) | M14: =IF(Setup!$C$23="","",Setup!$C$23) | N14: =IF(M14="","",SUMIF(Schedule!$D$6:$D$125,M14,Schedule!$P$6:$P$125)+SUMIF(Schedule!$G$6:$G$125,M14,Schedule!$P$6:$P$125)) | O14: =IF(M14="","",COUNTIF(Schedule!$H$6:$H$125,M14)) | P14: =IF(M14="","",COUNTIFS(Schedule!$D$6:$D$125,M14,Schedule!$H$6:$H$125,"Tie")+COUNTIFS(Schedule!$G$6:$G$125,M14,Schedule!$H$6:$H$125,"Tie")) | Q14: =IF(M14="","",N14-O14-P14) | R14: =IF(M14="","",SUMIFS(Schedule!$E$6:$E$125,Schedule!$D$6:$D$125,M14,Schedule!$P$6:$P$125,1)+SUMIFS(Schedule!$F$6:$F$125,Schedule!$G$6:$G$125,M14,Schedule!$P$6:$P$125,1)) | S14: =IF(M14="","",SUMIFS(Schedule!$F$6:$F$125,Schedule!$D$6:$D$125,M14,Schedule!$P$6:$P$125,1)+SUMIFS(Schedule!$E$6:$E$125,Schedule!$G$6:$G$125,M14,Schedule!$P$6:$P$125,1)) | T14: =IF(M14="","",R14-S14) | U14: =IF(M14="","",O14*Setup!$C$9+P14*Setup!$C$10) | V14: =IF(M14="","",U14*1000000+(T14+1000)*1000+R14+(100-ROW())/1000) | W14: =IF(ROW()-6>COUNT($V$7:$V$22),"",MATCH(LARGE($V$7:$V$22,ROW()-6),$V$7:$V$22,0))
B15: =IF(W15="","",ROW()-6) | C15: =IF(W15="","",INDEX($M$7:$M$22,W15)) | D15: =IF(W15="","",INDEX($N$7:$N$22,W15)) | E15: =IF(W15="","",INDEX($O$7:$O$22,W15)) | F15: =IF(W15="","",INDEX($P$7:$P$22,W15)) | G15: =IF(W15="","",INDEX($Q$7:$Q$22,W15)) | H15: =IF(W15="","",INDEX($R$7:$R$22,W15)) | I15: =IF(W15="","",INDEX($S$7:$S$22,W15)) | J15: =IF(W15="","",INDEX($T$7:$T$22,W15)) | K15: =IF(W15="","",INDEX($U$7:$U$22,W15)) | M15: =IF(Setup!$C$24="","",Setup!$C$24) | N15: =IF(M15="","",SUMIF(Schedule!$D$6:$D$125,M15,Schedule!$P$6:$P$125)+SUMIF(Schedule!$G$6:$G$125,M15,Schedule!$P$6:$P$125)) | O15: =IF(M15="","",COUNTIF(Schedule!$H$6:$H$125,M15)) | P15: =IF(M15="","",COUNTIFS(Schedule!$D$6:$D$125,M15,Schedule!$H$6:$H$125,"Tie")+COUNTIFS(Schedule!$G$6:$G$125,M15,Schedule!$H$6:$H$125,"Tie")) | Q15: =IF(M15="","",N15-O15-P15) | R15: =IF(M15="","",SUMIFS(Schedule!$E$6:$E$125,Schedule!$D$6:$D$125,M15,Schedule!$P$6:$P$125,1)+SUMIFS(Schedule!$F$6:$F$125,Schedule!$G$6:$G$125,M15,Schedule!$P$6:$P$125,1)) | S15: =IF(M15="","",SUMIFS(Schedule!$F$6:$F$125,Schedule!$D$6:$D$125,M15,Schedule!$P$6:$P$125,1)+SUMIFS(Schedule!$E$6:$E$125,Schedule!$G$6:$G$125,M15,Schedule!$P$6:$P$125,1)) | T15: =IF(M15="","",R15-S15) | U15: =IF(M15="","",O15*Setup!$C$9+P15*Setup!$C$10) | V15: =IF(M15="","",U15*1000000+(T15+1000)*1000+R15+(100-ROW())/1000) | W15: =IF(ROW()-6>COUNT($V$7:$V$22),"",MATCH(LARGE($V$7:$V$22,ROW()-6),$V$7:$V$22,0))
B16: =IF(W16="","",ROW()-6) | C16: =IF(W16="","",INDEX($M$7:$M$22,W16)) | D16: =IF(W16="","",INDEX($N$7:$N$22,W16)) | E16: =IF(W16="","",INDEX($O$7:$O$22,W16)) | F16: =IF(W16="","",INDEX($P$7:$P$22,W16)) | G16: =IF(W16="","",INDEX($Q$7:$Q$22,W16)) | H16: =IF(W16="","",INDEX($R$7:$R$22,W16)) | I16: =IF(W16="","",INDEX($S$7:$S$22,W16)) | J16: =IF(W16="","",INDEX($T$7:$T$22,W16)) | K16: =IF(W16="","",INDEX($U$7:$U$22,W16)) | M16: =IF(Setup!$C$25="","",Setup!$C$25) | N16: =IF(M16="","",SUMIF(Schedule!$D$6:$D$125,M16,Schedule!$P$6:$P$125)+SUMIF(Schedule!$G$6:$G$125,M16,Schedule!$P$6:$P$125)) | O16: =IF(M16="","",COUNTIF(Schedule!$H$6:$H$125,M16)) | P16: =IF(M16="","",COUNTIFS(Schedule!$D$6:$D$125,M16,Schedule!$H$6:$H$125,"Tie")+COUNTIFS(Schedule!$G$6:$G$125,M16,Schedule!$H$6:$H$125,"Tie")) | Q16: =IF(M16="","",N16-O16-P16) | R16: =IF(M16="","",SUMIFS(Schedule!$E$6:$E$125,Schedule!$D$6:$D$125,M16,Schedule!$P$6:$P$125,1)+SUMIFS(Schedule!$F$6:$F$125,Schedule!$G$6:$G$125,M16,Schedule!$P$6:$P$125,1)) | S16: =IF(M16="","",SUMIFS(Schedule!$F$6:$F$125,Schedule!$D$6:$D$125,M16,Schedule!$P$6:$P$125,1)+SUMIFS(Schedule!$E$6:$E$125,Schedule!$G$6:$G$125,M16,Schedule!$P$6:$P$125,1)) | T16: =IF(M16="","",R16-S16) | U16: =IF(M16="","",O16*Setup!$C$9+P16*Setup!$C$10) | V16: =IF(M16="","",U16*1000000+(T16+1000)*1000+R16+(100-ROW())/1000) | W16: =IF(ROW()-6>COUNT($V$7:$V$22),"",MATCH(LARGE($V$7:$V$22,ROW()-6),$V$7:$V$22,0))
B17: =IF(W17="","",ROW()-6) | C17: =IF(W17="","",INDEX($M$7:$M$22,W17)) | D17: =IF(W17="","",INDEX($N$7:$N$22,W17)) | E17: =IF(W17="","",INDEX($O$7:$O$22,W17)) | F17: =IF(W17="","",INDEX($P$7:$P$22,W17)) | G17: =IF(W17="","",INDEX($Q$7:$Q$22,W17)) | H17: =IF(W17="","",INDEX($R$7:$R$22,W17)) | I17: =IF(W17="","",INDEX($S$7:$S$22,W17)) | J17: =IF(W17="","",INDEX($T$7:$T$22,W17)) | K17: =IF(W17="","",INDEX($U$7:$U$22,W17)) | M17: =IF(Setup!$C$26="","",Setup!$C$26) | N17: =IF(M17="","",SUMIF(Schedule!$D$6:$D$125,M17,Schedule!$P$6:$P$125)+SUMIF(Schedule!$G$6:$G$125,M17,Schedule!$P$6:$P$125)) | O17: =IF(M17="","",COUNTIF(Schedule!$H$6:$H$125,M17)) | P17: =IF(M17="","",COUNTIFS(Schedule!$D$6:$D$125,M17,Schedule!$H$6:$H$125,"Tie")+COUNTIFS(Schedule!$G$6:$G$125,M17,Schedule!$H$6:$H$125,"Tie")) | Q17: =IF(M17="","",N17-O17-P17) | R17: =IF(M17="","",SUMIFS(Schedule!$E$6:$E$125,Schedule!$D$6:$D$125,M17,Schedule!$P$6:$P$125,1)+SUMIFS(Schedule!$F$6:$F$125,Schedule!$G$6:$G$125,M17,Schedule!$P$6:$P$125,1)) | S17: =IF(M17="","",SUMIFS(Schedule!$F$6:$F$125,Schedule!$D$6:$D$125,M17,Schedule!$P$6:$P$125,1)+SUMIFS(Schedule!$E$6:$E$125,Schedule!$G$6:$G$125,M17,Schedule!$P$6:$P$125,1)) | T17: =IF(M17="","",R17-S17) | U17: =IF(M17="","",O17*Setup!$C$9+P17*Setup!$C$10) | V17: =IF(M17="","",U17*1000000+(T17+1000)*1000+R17+(100-ROW())/1000) | W17: =IF(ROW()-6>COUNT($V$7:$V$22),"",MATCH(LARGE($V$7:$V$22,ROW()-6),$V$7:$V$22,0))
B18: =IF(W18="","",ROW()-6) | C18: =IF(W18="","",INDEX($M$7:$M$22,W18)) | D18: =IF(W18="","",INDEX($N$7:$N$22,W18)) | E18: =IF(W18="","",INDEX($O$7:$O$22,W18)) | F18: =IF(W18="","",INDEX($P$7:$P$22,W18)) | G18: =IF(W18="","",INDEX($Q$7:$Q$22,W18)) | H18: =IF(W18="","",INDEX($R$7:$R$22,W18)) | I18: =IF(W18="","",INDEX($S$7:$S$22,W18)) | J18: =IF(W18="","",INDEX($T$7:$T$22,W18)) | K18: =IF(W18="","",INDEX($U$7:$U$22,W18)) | M18: =IF(Setup!$C$27="","",Setup!$C$27) | N18: =IF(M18="","",SUMIF(Schedule!$D$6:$D$125,M18,Schedule!$P$6:$P$125)+SUMIF(Schedule!$G$6:$G$125,M18,Schedule!$P$6:$P$125)) | O18: =IF(M18="","",COUNTIF(Schedule!$H$6:$H$125,M18)) | P18: =IF(M18="","",COUNTIFS(Schedule!$D$6:$D$125,M18,Schedule!$H$6:$H$125,"Tie")+COUNTIFS(Schedule!$G$6:$G$125,M18,Schedule!$H$6:$H$125,"Tie")) | Q18: =IF(M18="","",N18-O18-P18) | R18: =IF(M18="","",SUMIFS(Schedule!$E$6:$E$125,Schedule!$D$6:$D$125,M18,Schedule!$P$6:$P$125,1)+SUMIFS(Schedule!$F$6:$F$125,Schedule!$G$6:$G$125,M18,Schedule!$P$6:$P$125,1)) | S18: =IF(M18="","",SUMIFS(Schedule!$F$6:$F$125,Schedule!$D$6:$D$125,M18,Schedule!$P$6:$P$125,1)+SUMIFS(Schedule!$E$6:$E$125,Schedule!$G$6:$G$125,M18,Schedule!$P$6:$P$125,1)) | T18: =IF(M18="","",R18-S18) | U18: =IF(M18="","",O18*Setup!$C$9+P18*Setup!$C$10) | V18: =IF(M18="","",U18*1000000+(T18+1000)*1000+R18+(100-ROW())/1000) | W18: =IF(ROW()-6>COUNT($V$7:$V$22),"",MATCH(LARGE($V$7:$V$22,ROW()-6),$V$7:$V$22,0))
B19: =IF(W19="","",ROW()-6) | C19: =IF(W19="","",INDEX($M$7:$M$22,W19)) | D19: =IF(W19="","",INDEX($N$7:$N$22,W19)) | E19: =IF(W19="","",INDEX($O$7:$O$22,W19)) | F19: =IF(W19="","",INDEX($P$7:$P$22,W19)) | G19: =IF(W19="","",INDEX($Q$7:$Q$22,W19)) | H19: =IF(W19="","",INDEX($R$7:$R$22,W19)) | I19: =IF(W19="","",INDEX($S$7:$S$22,W19)) | J19: =IF(W19="","",INDEX($T$7:$T$22,W19)) | K19: =IF(W19="","",INDEX($U$7:$U$22,W19)) | M19: =IF(Setup!$C$28="","",Setup!$C$28) | N19: =IF(M19="","",SUMIF(Schedule!$D$6:$D$125,M19,Schedule!$P$6:$P$125)+SUMIF(Schedule!$G$6:$G$125,M19,Schedule!$P$6:$P$125)) | O19: =IF(M19="","",COUNTIF(Schedule!$H$6:$H$125,M19)) | P19: =IF(M19="","",COUNTIFS(Schedule!$D$6:$D$125,M19,Schedule!$H$6:$H$125,"Tie")+COUNTIFS(Schedule!$G$6:$G$125,M19,Schedule!$H$6:$H$125,"Tie")) | Q19: =IF(M19="","",N19-O19-P19) | R19: =IF(M19="","",SUMIFS(Schedule!$E$6:$E$125,Schedule!$D$6:$D$125,M19,Schedule!$P$6:$P$125,1)+SUMIFS(Schedule!$F$6:$F$125,Schedule!$G$6:$G$125,M19,Schedule!$P$6:$P$125,1)) | S19: =IF(M19="","",SUMIFS(Schedule!$F$6:$F$125,Schedule!$D$6:$D$125,M19,Schedule!$P$6:$P$125,1)+SUMIFS(Schedule!$E$6:$E$125,Schedule!$G$6:$G$125,M19,Schedule!$P$6:$P$125,1)) | T19: =IF(M19="","",R19-S19) | U19: =IF(M19="","",O19*Setup!$C$9+P19*Setup!$C$10) | V19: =IF(M19="","",U19*1000000+(T19+1000)*1000+R19+(100-ROW())/1000) | W19: =IF(ROW()-6>COUNT($V$7:$V$22),"",MATCH(LARGE($V$7:$V$22,ROW()-6),$V$7:$V$22,0))
B20: =IF(W20="","",ROW()-6) | C20: =IF(W20="","",INDEX($M$7:$M$22,W20)) | D20: =IF(W20="","",INDEX($N$7:$N$22,W20)) | E20: =IF(W20="","",INDEX($O$7:$O$22,W20)) | F20: =IF(W20="","",INDEX($P$7:$P$22,W20)) | G20: =IF(W20="","",INDEX($Q$7:$Q$22,W20)) | H20: =IF(W20="","",INDEX($R$7:$R$22,W20)) | I20: =IF(W20="","",INDEX($S$7:$S$22,W20)) | J20: =IF(W20="","",INDEX($T$7:$T$22,W20)) | K20: =IF(W20="","",INDEX($U$7:$U$22,W20)) | M20: =IF(Setup!$C$29="","",Setup!$C$29) | N20: =IF(M20="","",SUMIF(Schedule!$D$6:$D$125,M20,Schedule!$P$6:$P$125)+SUMIF(Schedule!$G$6:$G$125,M20,Schedule!$P$6:$P$125)) | O20: =IF(M20="","",COUNTIF(Schedule!$H$6:$H$125,M20)) | P20: =IF(M20="","",COUNTIFS(Schedule!$D$6:$D$125,M20,Schedule!$H$6:$H$125,"Tie")+COUNTIFS(Schedule!$G$6:$G$125,M20,Schedule!$H$6:$H$125,"Tie")) | Q20: =IF(M20="","",N20-O20-P20) | R20: =IF(M20="","",SUMIFS(Schedule!$E$6:$E$125,Schedule!$D$6:$D$125,M20,Schedule!$P$6:$P$125,1)+SUMIFS(Schedule!$F$6:$F$125,Schedule!$G$6:$G$125,M20,Schedule!$P$6:$P$125,1)) | S20: =IF(M20="","",SUMIFS(Schedule!$F$6:$F$125,Schedule!$D$6:$D$125,M20,Schedule!$P$6:$P$125,1)+SUMIFS(Schedule!$E$6:$E$125,Schedule!$G$6:$G$125,M20,Schedule!$P$6:$P$125,1)) | T20: =IF(M20="","",R20-S20) | U20: =IF(M20="","",O20*Setup!$C$9+P20*Setup!$C$10) | V20: =IF(M20="","",U20*1000000+(T20+1000)*1000+R20+(100-ROW())/1000) | W20: =IF(ROW()-6>COUNT($V$7:$V$22),"",MATCH(LARGE($V$7:$V$22,ROW()-6),$V$7:$V$22,0))
